Workbook

Sheet Data
B2: Vessel's Dimension | D2: Unit | E2: Value | H2: Vessel's model mesh
B3: Length Overall | C3: LOA | D3: m | E3: 93.45
B4: Length Between Perpendicular | C4: LBP | D4: m | E4: 81.6
B5: Breadth | C5: B | D5: m | E5: 22
B6: Depth | C6: D | D6: m | E6: 8.5 | F6: Diodore | G6: Difference (%)
B7: Displacement | C7: M | D7: Tons | E7: 8231.1 | F7: =8074.802*1.025 -> 8276.672 | G7: =(F7-E7)/E7 -> 0.0055365686
B8: Draft - Mid | C8: T | D8: m | E8: 6.247
B9: Draft - Aft (AP) | D9: m | E9: 6.319
B10: Draft - Fwd (FP) | D10: m | E10: 6.176
B11: Trim | D11: m | E11: =E10-E9 -> -0.143
D12: ° | E12: =ATAN(E11/E4)*PI()/180 -> -3.0586008e-05
B13: Heel | C13: ° | D13: ° | E13: 0
B14: Centre of Gravity | C14: LCG | D14: m | E14: 40.5
C15: TCG | D15: m | E15: 0
C16: VCG | D16: m | E16: 8.05
B17: Corrected GM | C17: GM | D17: m | E17: 3.09
B19: Inertia
B20: Ixx | C20: =(E7*1000)*((E5/3)^2) -> 4.4265027e+08
B21: Iyy | C21: =(E7*1000)*((E4/4)^2) -> 3.4254546e+09
B22: Izz | C22: =(E7*1000)*((E4/4)^2) -> 3.4254546e+09
B24: Water Depth | C24: 300 | D24: m
B26: Rho | C26: 1025 | H26: Vessel's Lines Plan
B27: Cd | C27: 0.08
B28: Bq | C28: =0.5*C26*C27*E4*(E5^4) -> 7.8372687e+08 | D28: kg/m

Sheet Convention
A1: Conventions:
A2: Translations are amplitudes of response to a wave of unit amplitude
A3: Rotations are amplitudes, in degrees, of response to a wave of unit amplitude
A4: Phases are relative to potential
A5: Motions are positive when surge is forward, sway is to port, heave is up,
A6: roll is starboard down, pitch is bow down, yaw is bow to port
A9: Wave incidence
A10: 0° | B10: Following Wave
A11: 45° | B11: Quartering Following Wave (from stbd)
A12: 90° | B12: Beam Wave (from stbd)
A13: 135° | B13: Quartering Bow Wave (from stbd)
A14: 180° | B14: Head Wave
A16: Definition of RAO
A17: For any motion G(t) described by its RAO Ĝ(w), the response in a regular wave of amplitude a, pulsation w and phase j, is given by the expression:
A23: where | B23: |Ĝ(w)| is the module of the RAO
B24: arg(Ĝ(w)) is the phase of the RAO

Sheet ASN.HDB
A1: [SOFT] | B1: DIODORE
A2: [VERSION] | B2: 5.5.2
A3: [Date] | B3: 0.68716435 | C3: Jan | D3: 17 | E3: 2024
A4: [INPUT_FILE] | B4: ASN.INP
A5: [Locally_At] | B5: C:\Work_Faiz\New | C5: folder\02_Dio\Cd_0.08
A6: [UNIT]
A7: [FORWARD_SPEED] | B7: 0
A8: [HYDRO_PARA] | B8: Y
A9: [DETAIL_EXC] | B9: N
A10: [RAO] | B10: Y
A11: [DRIFT_FORCE] | B11: Y
A12: [QTF] | B12: N
A13: [PERIODS_NUMBER] | B13: 33
A14: [INTER_PERIODS_NB] | B14: 200
A15: [QTF_PERIODS_NUMBER] | B15: 0
A16: [QTF_SWEEPING_NUMBER] | B16: 0
A17: [QTF_SWEEPING_STEP] | B17: 0
A18: [HEADINGS_NUMBER] | B18: 37
A19: [LOWEST_HEADING] | B19: 0
A20: [HIGHEST_HEADING] | B20: 360
A21: [List_calculated_periods]
B22: 3
B23: 4
B24: 5
B25: 6
B26: 7
B27: 8
B28: 9
B29: 10
B30: 11
B31: 12
B32: 13
B33: 14
... B54: 35
A55: [List_calculated_headings]
B56: 0
B57: 10
B58: 20
B59: 30
B60: 40
...

Sheet 0°
A1: RAOs for Ile de Molene
A3: Direction = 0°
A4: Period | B4: Surge | D4: Sway | F4: Heave | H4: Roll | J4: Pitch | L4: Yaw
B5: Ampl. | C5: Phase | D5: Ampl. | E5: Phase | F5: Ampl. | G5: Phase | H5: Ampl. | I5: Phase | J5: Ampl. | K5: Phase | L5: Ampl. | M5: Phase
A6: (s) | B6: m/m | C6: deg | D6: m/m | E6: deg | F6: m/m | G6: deg | H6: deg/m | I6: deg | J6: deg/m | K6: deg | L6: deg/m | M6: deg
A7: 3 | B7: =ASN.HDB!C2639 -> 0.0057567591 | C7: =ASN.HDB!C3897 -> 293.62726 | D7: =ASN.HDB!D2639 -> 9.6417498e-06 | E7: =ASN.HDB!D3897 -> 248.54221 | F7: =ASN.HDB!E2639 -> 0.0067995694 | G7: =ASN.HDB!E3897 -> 306.91647 | H7: =ASN.HDB!F2639 -> 3.9623377e-05 | I7: =ASN.HDB!F3897 -> 73.856857 | J7: =ASN.HDB!G2639 -> 0.056186736 | K7: =ASN.HDB!G3897 -> 306.79584 | L7: =ASN.HDB!H2639 -> 3.0526557e-05 | M7: =ASN.HDB!H3897 -> 71.252998
A8: 4 | B8: =ASN.HDB!C2640 -> 0.01017687 | C8: =ASN.HDB!C3898 -> 329.24655 | D8: =ASN.HDB!D2640 -> 6.2938025e-06 | E8: =ASN.HDB!D3898 -> 244.6425 | F8: =ASN.HDB!E2640 -> 0.023505453 | G8: =ASN.HDB!E3898 -> 0.74357998 | H8: =ASN.HDB!F2640 -> 8.2385508e-05 | I8: =ASN.HDB!F3898 -> 104.7973 | J8: =ASN.HDB!G2640 -> 0.19417262 | K8: =ASN.HDB!G3898 -> 355.20355 | L8: =ASN.HDB!H2640 -> 2.1987353e-05 | M8: =ASN.HDB!H3898 -> 190.49689
A9: 5 | B9: =ASN.HDB!C2641 -> 0.012325233 | C9: =ASN.HDB!C3899 -> 213.95735 | D9: =ASN.HDB!D2641 -> 6.3118655e-06 | E9: =ASN.HDB!D3899 -> 287.74878 | F9: =ASN.HDB!E2641 -> 0.075872302 | G9: =ASN.HDB!E3899 -> 4.3794312 | H9: =ASN.HDB!F2641 -> 0.00012688563 | I9: =ASN.HDB!F3899 -> 121.9771 | J9: =ASN.HDB!G2641 -> 0.53986263 | K9: =ASN.HDB!G3899 -> 8.395401 | L9: =ASN.HDB!H2641 -> 1.9595556e-05 | M9: =ASN.HDB!H3899 -> 155.07898
A10: 6 | B10: =ASN.HDB!C2642 -> 0.038385224 | C10: =ASN.HDB!C3900 -> 152.47737 | D10: =ASN.HDB!D2642 -> 1.1383651e-05 | E10: =ASN.HDB!D3900 -> 307.72131 | F10: =ASN.HDB!E2642 -> 0.154076 | G10: =ASN.HDB!E3900 -> 344.2861 | H10: =ASN.HDB!F2642 -> 3.7507638e-05 | I10: =ASN.HDB!F3900 -> 20.102758 | J10: =ASN.HDB!G2642 -> 0.96908993 | K10: =ASN.HDB!G3900 -> 341.99841 | L10: =ASN.HDB!H2642 -> 2.2007755e-05 | M10: =ASN.HDB!H3900 -> 202.72205
A11: 7 | B11: =ASN.HDB!C2643 -> 0.12344672 | C11: =ASN.HDB!C3901 -> 182.82388 | D11: =ASN.HDB!D2643 -> 2.884837e-05 | E11: =ASN.HDB!D3901 -> 287.83575 | F11: =ASN.HDB!E2643 -> 0.22526895 | G11: =ASN.HDB!E3901 -> 251.75502 | H11: =ASN.HDB!F2643 -> 0.00034156878 | I11: =ASN.HDB!F3901 -> 230.93234 | J11: =ASN.HDB!G2643 -> 1.6049048 | K11: =ASN.HDB!G3901 -> 351.58609 | L11: =ASN.HDB!H2643 -> 6.6261629e-05 | M11: =ASN.HDB!H3901 -> 227.56601
A12: 8 | B12: =ASN.HDB!C2644 -> 0.3873665 | C12: =ASN.HDB!C3902 -> 146.04472 | D12: =ASN.HDB!D2644 -> 4.8359885e-05 | E12: =ASN.HDB!D3902 -> 224.41388 | F12: =ASN.HDB!E2644 -> 0.32122517 | G12: =ASN.HDB!E3902 -> 116.02752 | H12: =ASN.HDB!F2644 -> 0.0016290507 | I12: =ASN.HDB!F3902 -> 172.96036 | J12: =ASN.HDB!G2644 -> 2.8227074 | K12: =ASN.HDB!G3902 -> 312.82169 | L12: =ASN.HDB!H2644 -> 0.00019341271 | M12: =ASN.HDB!H3902 -> 187.1888
A13: 9 | B13: =ASN.HDB!C2645 -> 0.58417028 | C13: =ASN.HDB!C3903 -> 111.03628 | D13: =ASN.HDB!D2645 -> 7.1265218e-05 | E13: =ASN.HDB!D3903 -> 158.34692 | F13: =ASN.HDB!E2645 -> 0.55436152 | G13: =ASN.HDB!E3903 -> 50.737892 | H13: =ASN.HDB!F2645 -> 0.0059878593 | I13: =ASN.HDB!F3903 -> 123.13761 | J13: =ASN.HDB!G2645 -> 2.8306262 | K13: =ASN.HDB!G3903 -> 278.16431 | L13: =ASN.HDB!H2645 -> 0.00016623367 | M13: =ASN.HDB!H3903 -> 151.56654
A14: 10 | B14: =ASN.HDB!C2646 -> 0.69684231 | C14: =ASN.HDB!C3904 -> 87.978966 | D14: =ASN.HDB!D2646 -> 2.7673881e-05 | E14: =ASN.HDB!D3904 -> 332.94711 | F14: =ASN.HDB!E2646 -> 0.71041203 | G14: =ASN.HDB!E3904 -> 16.632202 | H14: =ASN.HDB!F2646 -> 0.011518042 | I14: =ASN.HDB!F3904 -> 274.23285 | J14: =ASN.HDB!G2646 -> 2.4402542 | K14: =ASN.HDB!G3904 -> 256.05487 | L14: =ASN.HDB!H2646 -> 0.00079085852 | M14: =ASN.HDB!H3904 -> 100.51197
A15: 11 | B15: =ASN.HDB!C2647 -> 0.77014452 | C15: =ASN.HDB!C3905 -> 72.132454 | D15: =ASN.HDB!D2647 -> 3.8212082e-05 | E15: =ASN.HDB!D3905 -> 44.105492 | F15: =ASN.HDB!E2647 -> 0.80493498 | G15: =ASN.HDB!E3905 -> 354.95261 | H15: =ASN.HDB!F2647 -> 0.0033065183 | I15: =ASN.HDB!F3905 -> 245.5219 | J15: =ASN.HDB!G2647 -> 2.06201 | K15: =ASN.HDB!G3905 -> 241.44324 | L15: =ASN.HDB!H2647 -> 0.00054427522 | M15: =ASN.HDB!H3905 -> 71.840523
A16: 12 | B16: =ASN.HDB!C2648 -> 0.82212967 | C16: =ASN.HDB!C3906 -> 60.479191 | D16: =ASN.HDB!D2648 -> 5.7277888e-05 | E16: =ASN.HDB!D3906 -> 22.926687 | F16: =ASN.HDB!E2648 -> 0.86366564 | G16: =ASN.HDB!E3906 -> 339.8161 | H16: =ASN.HDB!F2648 -> 0.0019639374 | I16: =ASN.HDB!F3906 -> 224.18973 | J16: =ASN.HDB!G2648 -> 1.7532462 | K16: =ASN.HDB!G3906 -> 231.01736 | L16: =ASN.HDB!H2648 -> 0.00052269694 | M16: =ASN.HDB!H3906 -> 47.456985
A17: 13 | B17: =ASN.HDB!C2649 -> 0.86020732 | C17: =ASN.HDB!C3907 -> 51.524109 | D17: =ASN.HDB!D2649 -> 7.3785552e-05 | E17: =ASN.HDB!D3907 -> 4.8799238 | F17: =ASN.HDB!E2649 -> 0.90164953 | G17: =ASN.HDB!E3907 -> 328.64676 | H17: =ASN.HDB!F2649 -> 0.0014094077 | I17: =ASN.HDB!F3907 -> 207.84535 | J17: =ASN.HDB!G2649 -> 1.5053993 | K17: =ASN.HDB!G3907 -> 223.1487 | L17: =ASN.HDB!H2649 -> 0.00053762097 | M17: =ASN.HDB!H3907 -> 27.159037
A18: 14 | B18: =ASN.HDB!C2650 -> 0.88858211 | C18: =ASN.HDB!C3908 -> 44.446602 | D18: =ASN.HDB!D2650 -> 8.7540146e-05 | E18: =ASN.HDB!D3908 -> 351.50647 | F18: =ASN.HDB!E2650 -> 0.92717624 | G18: =ASN.HDB!E3908 -> 320.08853 | H18: =ASN.HDB!F2650 -> 0.0011156513 | I18: =ASN.HDB!F3908 -> 193.47516 | J18: =ASN.HDB!G2650 -> 1.3048537 | K18: =ASN.HDB!G3908 -> 216.99095 | L18: =ASN.HDB!H2650 -> 0.00057141006 | M18: =ASN.HDB!H3908 -> 10.245642
... A39: 35 | B39: =ASN.HDB!C2671 -> 1.1989132 | C39: =ASN.HDB!C3929 -> 8.484025 | D39: =ASN.HDB!D2671 -> 0.00042365631 | E39: =ASN.HDB!D3929 -> 283.5423 | F39: =ASN.HDB!E2671 -> 0.99741554 | G39: =ASN.HDB!E3929 -> 279.38394 | H39: =ASN.HDB!F2671 -> 0.00040080174 | I39: =ASN.HDB!F3929 -> 110.86937 | J39: =ASN.HDB!G2671 -> 0.25303501 | K39: =ASN.HDB!G3929 -> 186.41933 | L39: =ASN.HDB!H2671 -> 0.0026765415 | M39: =ASN.HDB!H3929 -> 285.02814

Sheet 10°
A1: ='0°'!A1 -> RAOs for Ile de Molene
A3: Direction = 10°
A4: Period | B4: Surge | D4: Sway | F4: Heave | H4: Roll | J4: Pitch | L4: Yaw
B5: Ampl. | C5: Phase | D5: Ampl. | E5: Phase | F5: Ampl. | G5: Phase | H5: Ampl. | I5: Phase | J5: Ampl. | K5: Phase | L5: Ampl. | M5: Phase
A6: (s) | B6: m/m | C6: deg | D6: m/m | E6: deg | F6: m/m | G6: deg | H6: deg/m | I6: deg | J6: deg/m | K6: deg | L6: deg/m | M6: deg
A7: 3 | B7: =ASN.HDB!C2673 -> 0.0054410701 | C7: =ASN.HDB!C3931 -> 297.73941 | D7: =ASN.HDB!D2673 -> 0.0012210021 | E7: =ASN.HDB!D3931 -> 259.60843 | F7: =ASN.HDB!E2673 -> 0.0062585738 | G7: =ASN.HDB!E3931 -> 306.50293 | H7: =ASN.HDB!F2673 -> 0.023688857 | I7: =ASN.HDB!F3931 -> 58.768917 | J7: =ASN.HDB!G2673 -> 0.052138206 | K7: =ASN.HDB!G3931 -> 306.31299 | L7: =ASN.HDB!H2673 -> 0.002638184 | M7: =ASN.HDB!H3931 -> 292.07181
A8: 4 | B8: =ASN.HDB!C2674 -> 0.0096208332 | C8: =ASN.HDB!C3932 -> 326.14401 | D8: =ASN.HDB!D2674 -> 0.0044297962 | E8: =ASN.HDB!D3932 -> 27.96459 | F8: =ASN.HDB!E2674 -> 0.023741649 | G8: =ASN.HDB!E3932 -> 1.414216 | H8: =ASN.HDB!F2674 -> 0.030541847 | I8: =ASN.HDB!F3932 -> 113.85907 | J8: =ASN.HDB!G2674 -> 0.1896354 | K8: =ASN.HDB!G3932 -> 355.25687 | L8: =ASN.HDB!H2674 -> 0.019006798 | M8: =ASN.HDB!H3932 -> 53.174248
A9: 5 | B9: =ASN.HDB!C2675 -> 0.011430471 | C9: =ASN.HDB!C3933 -> 207.2074 | D9: =ASN.HDB!D2675 -> 0.0034064935 | E9: =ASN.HDB!D3933 -> 358.1618 | F9: =ASN.HDB!E2675 -> 0.074395679 | G9: =ASN.HDB!E3933 -> 3.7751215 | H9: =ASN.HDB!F2675 -> 0.050867014 | I9: =ASN.HDB!F3933 -> 191.96165 | J9: =ASN.HDB!G2675 -> 0.54365605 | K9: =ASN.HDB!G3933 -> 8.0881805 | L9: =ASN.HDB!H2675 -> 0.037043266 | M9: =ASN.HDB!H3933 -> 321.69934
A10: 6 | B10: =ASN.HDB!C2676 -> 0.036285713 | C10: =ASN.HDB!C3934 -> 157.20848 | D10: =ASN.HDB!D2676 -> 0.01067061 | E10: =ASN.HDB!D3934 -> 83.202721 | F10: =ASN.HDB!E2676 -> 0.1608029 | G10: =ASN.HDB!E3934 -> 343.043 | H10: =ASN.HDB!F2676 -> 0.2498986 | I10: =ASN.HDB!F3934 -> 172.95572 | J10: =ASN.HDB!G2676 -> 0.94796139 | K10: =ASN.HDB!G3934 -> 343.11938 | L10: =ASN.HDB!H2676 -> 0.039257444 | M10: =ASN.HDB!H3934 -> 9.5265303
A11: 7 | B11: =ASN.HDB!C2677 -> 0.13229358 | C11: =ASN.HDB!C3935 -> 181.78477 | D11: =ASN.HDB!D2677 -> 0.013313401 | E11: =ASN.HDB!D3935 -> 185.95856 | F11: =ASN.HDB!E2677 -> 0.22221309 | G11: =ASN.HDB!E3935 -> 246.32835 | H11: =ASN.HDB!F2677 -> 0.22286396 | I11: =ASN.HDB!F3935 -> 173.79834 | J11: =ASN.HDB!G2677 -> 1.6801864 | K11: =ASN.HDB!G3935 -> 350.70215 | L11: =ASN.HDB!H2677 -> 0.17518604 | M11: =ASN.HDB!H3935 -> 284.59393
A12: 8 | B12: =ASN.HDB!C2678 -> 0.39408427 | C12: =ASN.HDB!C3936 -> 144.08606 | D12: =ASN.HDB!D2678 -> 0.045948811 | E12: =ASN.HDB!D3936 -> 140.94058 | F12: =ASN.HDB!E2678 -> 0.33253285 | G12: =ASN.HDB!E3936 -> 111.45274 | H12: =ASN.HDB!F2678 -> 0.41684288 | I12: =ASN.HDB!F3936 -> 199.43826 | J12: =ASN.HDB!G2678 -> 2.8538907 | K12: =ASN.HDB!G3936 -> 311.01462 | L12: =ASN.HDB!H2678 -> 0.23820692 | M12: =ASN.HDB!H3936 -> 237.85463
A13: 9 | B13: =ASN.HDB!C2679 -> 0.58505881 | C13: =ASN.HDB!C3937 -> 109.43227 | D13: =ASN.HDB!D2679 -> 0.072964467 | E13: =ASN.HDB!D3937 -> 114.93928 | F13: =ASN.HDB!E2679 -> 0.56659073 | G13: =ASN.HDB!E3937 -> 48.260635 | H13: =ASN.HDB!F2679 -> 1.3823618 | I13: =ASN.HDB!F3937 -> 190.32362 | J13: =ASN.HDB!G2679 -> 2.8251143 | K13: =ASN.HDB!G3937 -> 276.65253 | L13: =ASN.HDB!H2679 -> 0.22305475 | M13: =ASN.HDB!H3937 -> 208.39818
A14: 10 | B14: =ASN.HDB!C2680 -> 0.6932711 | C14: =ASN.HDB!C3938 -> 86.673767 | D14: =ASN.HDB!D2680 -> 0.11163782 | E14: =ASN.HDB!D3938 -> 88.477585 | F14: =ASN.HDB!E2680 -> 0.71952158 | G14: =ASN.HDB!E3938 -> 14.889695 | H14: =ASN.HDB!F2680 -> 2.3541496 | I14: =ASN.HDB!F3938 -> 57.873749 | J14: =ASN.HDB!G2680 -> 2.4222105 | K14: =ASN.HDB!G3938 -> 254.8243 | L14: =ASN.HDB!H2680 -> 0.30913207 | M14: =ASN.HDB!H3938 -> 197.74611
A15: 11 | B15: =ASN.HDB!C2681 -> 0.76353329 | C15: =ASN.HDB!C3939 -> 71.050636 | D15: =ASN.HDB!D2681 -> 0.11974214 | E15: =ASN.HDB!D3939 -> 72.701874 | F15: =ASN.HDB!E2681 -> 0.81142521 | G15: =ASN.HDB!E3939 -> 353.60574 | H15: =ASN.HDB!F2681 -> 0.82608712 | I15: =ASN.HDB!F3939 -> 25.037594 | J15: =ASN.HDB!G2681 -> 2.0411162 | K15: =ASN.HDB!G3939 -> 240.42538 | L15: =ASN.HDB!H2681 -> 0.2598981 | M15: =ASN.HDB!H3939 -> 174.55319
A16: 12 | B16: =ASN.HDB!C2682 -> 0.813389 | C16: =ASN.HDB!C3940 -> 59.567688 | D16: =ASN.HDB!D2682 -> 0.13073628 | E16: =ASN.HDB!D3940 -> 61.492149 | F16: =ASN.HDB!E2682 -> 0.86833024 | G16: =ASN.HDB!E3940 -> 338.72604 | H16: =ASN.HDB!F2682 -> 0.49930078 | I16: =ASN.HDB!F3940 -> 20.207037 | J16: =ASN.HDB!G2682 -> 1.7327185 | K16: =ASN.HDB!G3940 -> 230.15977 | L16: =ASN.HDB!H2682 -> 0.22686051 | M16: =ASN.HDB!H3940 -> 163.05592
A17: 13 | B17: =ASN.HDB!C2683 -> 0.84994662 | C17: =ASN.HDB!C3941 -> 50.745876 | D17: =ASN.HDB!D2683 -> 0.1393356 | E17: =ASN.HDB!D3941 -> 52.543468 | F17: =ASN.HDB!E2683 -> 0.90506709 | G17: =ASN.HDB!E3941 -> 327.73911 | H17: =ASN.HDB!F2683 -> 0.35921401 | I17: =ASN.HDB!F3941 -> 17.497469 | J17: =ASN.HDB!G2683 -> 1.486285 | K17: =ASN.HDB!G3941 -> 222.41508 | L17: =ASN.HDB!H2683 -> 0.20046408 | M17: =ASN.HDB!H3941 -> 154.89265
A18: 14 | B18: =ASN.HDB!C2684 -> 0.87721819 | C18: =ASN.HDB!C3942 -> 43.774467 | D18: =ASN.HDB!D2684 -> 0.14586499 | E18: =ASN.HDB!D3942 -> 45.365017 | F18: =ASN.HDB!E2684 -> 0.92973065 | G18: =ASN.HDB!E3942 -> 319.3176 | H18: =ASN.HDB!F2684 -> 0.27959299 | I18: =ASN.HDB!F3942 -> 15.458575 | J18: =ASN.HDB!G2684 -> 1.2874365 | K18: =ASN.HDB!G3942 -> 216.35551 | L18: =ASN.HDB!H2684 -> 0.1781926 | M18: =ASN.HDB!H3942 -> 148.92184
... A39: 35 | B39: =ASN.HDB!C2705 -> 1.1808009 | C39: =ASN.HDB!C3963 -> 8.3515654 | D39: =ASN.HDB!D2705 -> 0.20678967 | E39: =ASN.HDB!D3963 -> 8.644681 | F39: =ASN.HDB!E2705 -> 0.99751133 | G39: =ASN.HDB!E3963 -> 279.24136 | H39: =ASN.HDB!F2705 -> 0.039584674 | I39: =ASN.HDB!F3963 -> 4.0145049 | J39: =ASN.HDB!G2705 -> 0.24921061 | K39: =ASN.HDB!G3963 -> 186.28481 | L39: =ASN.HDB!H2705 -> 0.064592749 | M39: =ASN.HDB!H3963 -> 148.11609

Sheet 20°
A1: ='0°'!A1 -> RAOs for Ile de Molene
A3: Direction = 20°
A4: Period | B4: Surge | D4: Sway | F4: Heave | H4: Roll | J4: Pitch | L4: Yaw
B5: Ampl. | C5: Phase | D5: Ampl. | E5: Phase | F5: Ampl. | G5: Phase | H5: Ampl. | I5: Phase | J5: Ampl. | K5: Phase | L5: Ampl. | M5: Phase
A6: (s) | B6: m/m | C6: deg | D6: m/m | E6: deg | F6: m/m | G6: deg | H6: deg/m | I6: deg | J6: deg/m | K6: deg | L6: deg/m | M6: deg
A7: 3 | B7: =ASN.HDB!C2707 -> 0.0053911591 | C7: =ASN.HDB!C3965 -> 304.00595 | D7: =ASN.HDB!D2707 -> 0.0014405856 | E7: =ASN.HDB!D3965 -> 199.30547 | F7: =ASN.HDB!E2707 -> 0.0049070129 | G7: =ASN.HDB!E3965 -> 305.42593 | H7: =ASN.HDB!F2707 -> 0.046281781 | I7: =ASN.HDB!F3965 -> 66.704979 | J7: =ASN.HDB!G2707 -> 0.041066419 | K7: =ASN.HDB!G3965 -> 303.75662 | L7: =ASN.HDB!H2707 -> 0.0061968346 | M7: =ASN.HDB!H3965 -> 122.16402
A8: 4 | B8: =ASN.HDB!C2708 -> 0.0072261295 | C8: =ASN.HDB!C3966 -> 321.80688 | D8: =ASN.HDB!D2708 -> 0.0081220409 | E8: =ASN.HDB!D3966 -> 346.24667 | F8: =ASN.HDB!E2708 -> 0.024493838 | G8: =ASN.HDB!E3966 -> 1.0590112 | H8: =ASN.HDB!F2708 -> 0.042776551 | I8: =ASN.HDB!F3966 -> 141.68275 | J8: =ASN.HDB!G2708 -> 0.17890301 | K8: =ASN.HDB!G3966 -> 355.90475 | L8: =ASN.HDB!H2708 -> 0.02900503 | M8: =ASN.HDB!H3966 -> 0.39737791
A9: 5 | B9: =ASN.HDB!C2709 -> 0.0083709257 | C9: =ASN.HDB!C3967 -> 183.45244 | D9: =ASN.HDB!D2709 -> 0.0042266389 | E9: =ASN.HDB!D3967 -> 319.96567 | F9: =ASN.HDB!E2709 -> 0.069834873 | G9: =ASN.HDB!E3967 -> 3.3377063 | H9: =ASN.HDB!F2709 -> 0.1370202 | I9: =ASN.HDB!F3967 -> 204.6869 | J9: =ASN.HDB!G2709 -> 0.55307776 | K9: =ASN.HDB!G3967 -> 6.3288283 | L9: =ASN.HDB!H2709 -> 0.073549181 | M9: =ASN.HDB!H3967 -> 296.58014
A10: 6 | B10: =ASN.HDB!C2710 -> 0.034859665 | C10: =ASN.HDB!C3968 -> 174.97546 | D10: =ASN.HDB!D2710 -> 0.018710522 | E10: =ASN.HDB!D3968 -> 72.046303 | F10: =ASN.HDB!E2710 -> 0.17847116 | G10: =ASN.HDB!E3968 -> 337.88681 | H10: =ASN.HDB!F2710 -> 0.4583267 | I10: =ASN.HDB!F3968 -> 167.5331 | J10: =ASN.HDB!G2710 -> 0.9070825 | K10: =ASN.HDB!G3968 -> 347.90164 | L10: =ASN.HDB!H2710 -> 0.10352425 | M10: =ASN.HDB!H3968 -> 351.70367
A11: 7 | B11: =ASN.HDB!C2711 -> 0.15789741 | C11: =ASN.HDB!C3969 -> 177.67793 | D11: =ASN.HDB!D2711 -> 0.034039102 | E11: =ASN.HDB!D3969 -> 176.2919 | F11: =ASN.HDB!E2711 -> 0.21311685 | G11: =ASN.HDB!E3969 -> 229.01736 | H11: =ASN.HDB!F2711 -> 0.42618561 | I11: =ASN.HDB!F3969 -> 177.52806 | J11: =ASN.HDB!G2711 -> 1.9011378 | K11: =ASN.HDB!G3969 -> 347.25348 | L11: =ASN.HDB!H2711 -> 0.36090103 | M11: =ASN.HDB!H3969 -> 275.2767
A12: 8 | B12: =ASN.HDB!C2712 -> 0.41187018 | C12: =ASN.HDB!C3970 -> 138.25931 | D12: =ASN.HDB!D2712 -> 0.098691329 | E12: =ASN.HDB!D3970 -> 134.27211 | F12: =ASN.HDB!E2712 -> 0.36929184 | G12: =ASN.HDB!E3970 -> 98.574493 | H12: =ASN.HDB!F2712 -> 0.86690646 | I12: =ASN.HDB!F3970 -> 197.97844 | J12: =ASN.HDB!G2712 -> 2.9338672 | K12: =ASN.HDB!G3970 -> 305.59262 | L12: =ASN.HDB!H2712 -> 0.46828964 | M12: =ASN.HDB!H3970 -> 231.02901
A13: 9 | B13: =ASN.HDB!C2713 -> 0.58565146 | C13: =ASN.HDB!C3971 -> 104.66959 | D13: =ASN.HDB!D2713 -> 0.15242243 | E13: =ASN.HDB!D3971 -> 109.6087 | F13: =ASN.HDB!E2713 -> 0.60313761 | G13: =ASN.HDB!E3971 -> 41.061615 | H13: =ASN.HDB!F2713 -> 2.6424022 | I13: =ASN.HDB!F3971 -> 179.70976 | J13: =ASN.HDB!G2713 -> 2.8008449 | K13: =ASN.HDB!G3971 -> 272.14203 | L13: =ASN.HDB!H2713 -> 0.43501133 | M13: =ASN.HDB!H3971 -> 204.43198
A14: 10 | B14: =ASN.HDB!C2714 -> 0.68108833 | C14: =ASN.HDB!C3972 -> 82.796333 | D14: =ASN.HDB!D2714 -> 0.22133268 | E14: =ASN.HDB!D3972 -> 85.9963 | F14: =ASN.HDB!E2714 -> 0.74626589 | G14: =ASN.HDB!E3972 -> 9.7661228 | H14: =ASN.HDB!F2714 -> 3.8761249 | I14: =ASN.HDB!F3972 -> 69.436447 | J14: =ASN.HDB!G2714 -> 2.3643453 | K14: =ASN.HDB!G3972 -> 251.15555 | L14: =ASN.HDB!H2714 -> 0.55031961 | M14: =ASN.HDB!H3972 -> 194.5076
A15: 11 | B15: =ASN.HDB!C2715 -> 0.74268782 | C15: =ASN.HDB!C3973 -> 67.836418 | D15: =ASN.HDB!D2715 -> 0.24068305 | E15: =ASN.HDB!D3973 -> 69.505005 | F15: =ASN.HDB!E2715 -> 0.83034557 | G15: =ASN.HDB!E3973 -> 349.62674 | H15: =ASN.HDB!F2715 -> 1.6338537 | I15: =ASN.HDB!F3973 -> 26.918177 | J15: =ASN.HDB!G2715 -> 1.9765981 | K15: =ASN.HDB!G3973 -> 237.39021 | L15: =ASN.HDB!H2715 -> 0.49399304 | M15: =ASN.HDB!H3973 -> 171.96191
A16: 12 | B16: =ASN.HDB!C2716 -> 0.78651154 | C16: =ASN.HDB!C3974 -> 56.859833 | D16: =ASN.HDB!D2716 -> 0.26101229 | E16: =ASN.HDB!D3974 -> 58.707691 | F16: =ASN.HDB!E2716 -> 0.8818751 | G16: =ASN.HDB!E3974 -> 335.49869 | H16: =ASN.HDB!F2716 -> 0.98924977 | I16: =ASN.HDB!F3974 -> 20.225981 | J16: =ASN.HDB!G2716 -> 1.670261 | K16: =ASN.HDB!G3974 -> 227.60226 | L16: =ASN.HDB!H2716 -> 0.43078926 | M16: =ASN.HDB!H3974 -> 160.79367
A17: 13 | B17: =ASN.HDB!C2717 -> 0.81877178 | C17: =ASN.HDB!C3975 -> 48.433861 | D17: =ASN.HDB!D2717 -> 0.27707094 | E17: =ASN.HDB!D3975 -> 50.156124 | F17: =ASN.HDB!E2717 -> 0.91496772 | G17: =ASN.HDB!E3975 -> 325.04883 | H17: =ASN.HDB!F2717 -> 0.71098083 | I17: =ASN.HDB!F3975 -> 17.12546 | J17: =ASN.HDB!G2717 -> 1.4285903 | K17: =ASN.HDB!G3975 -> 220.22708 | L17: =ASN.HDB!H2717 -> 0.38010278 | M17: =ASN.HDB!H3975 -> 153.05821
A18: 14 | B18: =ASN.HDB!C2718 -> 0.84293091 | C18: =ASN.HDB!C3976 -> 41.777832 | D18: =ASN.HDB!D2718 -> 0.2893056 | E18: =ASN.HDB!D3976 -> 43.304276 | F18: =ASN.HDB!E2718 -> 0.93712616 | G18: =ASN.HDB!E3976 -> 317.03094 | H18: =ASN.HDB!F2718 -> 0.55295449 | I18: =ASN.HDB!F3976 -> 14.975395 | J18: =ASN.HDB!G2718 -> 1.2351048 | K18: =ASN.HDB!G3976 -> 214.45963 | L18: =ASN.HDB!H2718 -> 0.33763066 | M18: =ASN.HDB!H3976 -> 147.47076
... A39: 35 | B39: =ASN.HDB!C2739 -> 1.1269963 | C39: =ASN.HDB!C3997 -> 7.9580145 | D39: =ASN.HDB!D2739 -> 0.40736333 | E39: =ASN.HDB!D3997 -> 8.2996054 | F39: =ASN.HDB!E2739 -> 0.99779034 | G39: =ASN.HDB!E3997 -> 278.8179 | H39: =ASN.HDB!F2739 -> 0.078093834 | I39: =ASN.HDB!F3997 -> 3.6006711 | J39: =ASN.HDB!G2739 -> 0.23784745 | K39: =ASN.HDB!G3997 -> 185.88194 | L39: =ASN.HDB!H2739 -> 0.12652831 | M39: =ASN.HDB!H3997 -> 148.27589

Sheet 30°
A1: ='0°'!A1 -> RAOs for Ile de Molene
A3: Direction = 30°
A4: Period | B4: Surge | D4: Sway | F4: Heave | H4: Roll | J4: Pitch | L4: Yaw
B5: Ampl. | C5: Phase | D5: Ampl. | E5: Phase | F5: Ampl. | G5: Phase | H5: Ampl. | I5: Phase | J5: Ampl. | K5: Phase | L5: Ampl. | M5: Phase
A6: (s) | B6: m/m | C6: deg | D6: m/m | E6: deg | F6: m/m | G6: deg | H6: deg/m | I6: deg | J6: deg/m | K6: deg | L6: deg/m | M6: deg
A7: 3 | B7: =ASN.HDB!C2741 -> 0.0039519472 | C7: =ASN.HDB!C3999 -> 298.33939 | D7: =ASN.HDB!D2741 -> 0.0014078292 | E7: =ASN.HDB!D3999 -> 316.59021 | F7: =ASN.HDB!E2741 -> 0.0033670575 | G7: =ASN.HDB!E3999 -> 298.97495 | H7: =ASN.HDB!F2741 -> 0.05777093 | I7: =ASN.HDB!F3999 -> 56.546352 | J7: =ASN.HDB!G2741 -> 0.027262954 | K7: =ASN.HDB!G3999 -> 295.81964 | L7: =ASN.HDB!H2741 -> 0.0099270791 | M7: =ASN.HDB!H3999 -> 28.253862
A8: 4 | B8: =ASN.HDB!C2742 -> 0.0048147193 | C8: =ASN.HDB!C4000 -> 352.24179 | D8: =ASN.HDB!D2742 -> 0.0088149691 | E8: =ASN.HDB!D4000 -> 272.16107 | F8: =ASN.HDB!E2742 -> 0.024643317 | G8: =ASN.HDB!E4000 -> 355.92117 | H8: =ASN.HDB!F2742 -> 0.1189275 | I8: =ASN.HDB!F4000 -> 168.73105 | J8: =ASN.HDB!G2742 -> 0.17108656 | K8: =ASN.HDB!G4000 -> 356.46445 | L8: =ASN.HDB!H2742 -> 0.040229239 | M8: =ASN.HDB!H4000 -> 263.25006
A9: 5 | B9: =ASN.HDB!C2743 -> 0.0037355842 | C9: =ASN.HDB!C4001 -> 105.95259 | D9: =ASN.HDB!D2743 -> 0.0056491084 | E9: =ASN.HDB!D4001 -> 202.50194 | F9: =ASN.HDB!E2743 -> 0.065527663 | G9: =ASN.HDB!E4001 -> 7.1307521 | H9: =ASN.HDB!F2743 -> 0.30870157 | I9: =ASN.HDB!F4001 -> 200.57628 | J9: =ASN.HDB!G2743 -> 0.54969907 | K9: =ASN.HDB!G4001 -> 1.5796893 | L9: =ASN.HDB!H2743 -> 0.10010248 | M9: =ASN.HDB!H4001 -> 258.53574
A10: 6 | B10: =ASN.HDB!C2744 -> 0.047494229 | C10: =ASN.HDB!C4002 -> 194.32782 | D10: =ASN.HDB!D2744 -> 0.018785376 | E10: =ASN.HDB!D4002 -> 57.721828 | F10: =ASN.HDB!E2744 -> 0.19613941 | G10: =ASN.HDB!E4002 -> 326.17279 | H10: =ASN.HDB!F2744 -> 0.57489187 | I10: =ASN.HDB!F4002 -> 161.57103 | J10: =ASN.HDB!G2744 -> 0.94456333 | K10: =ASN.HDB!G4002 -> 357.75342 | L10: =ASN.HDB!H2744 -> 0.2166 | M10: =ASN.HDB!H4002 -> 326.12289
A11: 7 | B11: =ASN.HDB!C2745 -> 0.19623874 | C11: =ASN.HDB!C4003 -> 169.01231 | D11: =ASN.HDB!D2745 -> 0.069890551 | E11: =ASN.HDB!D4003 -> 160.95163 | F11: =ASN.HDB!E2745 -> 0.20464733 | G11: =ASN.HDB!E4003 -> 196.4408 | H11: =ASN.HDB!F2745 -> 0.63313723 | I11: =ASN.HDB!F4003 -> 183.75226 | J11: =ASN.HDB!G2745 -> 2.2402823 | K11: =ASN.HDB!G4003 -> 339.72833 | L11: =ASN.HDB!H2745 -> 0.55795854 | M11: =ASN.HDB!H4003 -> 260.04584
A12: 8 | B12: =ASN.HDB!C2746 -> 0.43366048 | C12: =ASN.HDB!C4004 -> 128.71417 | D12: =ASN.HDB!D2746 -> 0.16393742 | E12: =ASN.HDB!D4004 -> 123.35814 | F12: =ASN.HDB!E2746 -> 0.43772778 | G12: =ASN.HDB!E4004 -> 79.544502 | H12: =ASN.HDB!F2746 -> 1.3752223 | I12: =ASN.HDB!F4004 -> 195.03371 | J12: =ASN.HDB!G2746 -> 3.0225987 | K12: =ASN.HDB!G4004 -> 296.57077 | L12: =ASN.HDB!H2746 -> 0.67542797 | M12: =ASN.HDB!H4004 -> 219.8011
A13: 9 | B13: =ASN.HDB!C2747 -> 0.58003634 | C13: =ASN.HDB!C4005 -> 96.890259 | D13: =ASN.HDB!D2747 -> 0.24088335 | E13: =ASN.HDB!D4005 -> 100.80827 | F13: =ASN.HDB!E2747 -> 0.66307235 | G13: =ASN.HDB!E4005 -> 29.745403 | H13: =ASN.HDB!F2747 -> 3.7223001 | I13: =ASN.HDB!F4005 -> 168.99254 | J13: =ASN.HDB!G2747 -> 2.7361262 | K13: =ASN.HDB!G4005 -> 264.70428 | L13: =ASN.HDB!H2747 -> 0.61506563 | M13: =ASN.HDB!H4005 -> 196.62679
A14: 10 | B14: =ASN.HDB!C2748 -> 0.65610099 | C14: =ASN.HDB!C4006 -> 76.461441 | D14: =ASN.HDB!D2748 -> 0.33226591 | E14: =ASN.HDB!D4006 -> 80.022026 | F14: =ASN.HDB!E2748 -> 0.78878278 | G14: =ASN.HDB!E4006 -> 1.5414361 | H14: =ASN.HDB!F2748 -> 5.0405192 | I14: =ASN.HDB!F4006 -> 73.522972 | J14: =ASN.HDB!G2748 -> 2.2561495 | K14: =ASN.HDB!G4006 -> 245.11133 | L14: =ASN.HDB!H2748 -> 0.73037869 | M14: =ASN.HDB!H4006 -> 188.33215
A15: 11 | B15: =ASN.HDB!C2749 -> 0.70479947 | C15: =ASN.HDB!C4007 -> 62.585197 | D15: =ASN.HDB!D2749 -> 0.36261711 | E15: =ASN.HDB!D4007 -> 64.200584 | F15: =ASN.HDB!E2749 -> 0.86001348 | G15: =ASN.HDB!E4007 -> 343.18857 | H15: =ASN.HDB!F2749 -> 2.396699 | I15: =ASN.HDB!F4007 -> 27.828747 | J15: =ASN.HDB!G2749 -> 1.8634591 | K15: =ASN.HDB!G4007 -> 232.39046 | L15: =ASN.HDB!H2749 -> 0.67790395 | M15: =ASN.HDB!H4007 -> 167.58307
A16: 12 | B16: =ASN.HDB!C2750 -> 0.73971647 | C16: =ASN.HDB!C4008 -> 52.436424 | D16: =ASN.HDB!D2750 -> 0.38955417 | E16: =ASN.HDB!D4008 -> 54.134365 | F16: =ASN.HDB!E2750 -> 0.90295208 | G16: =ASN.HDB!E4008 -> 330.25751 | H16: =ASN.HDB!F2750 -> 1.4550053 | I16: =ASN.HDB!F4008 -> 19.53599 | J16: =ASN.HDB!G2750 -> 1.5636235 | K16: =ASN.HDB!G4008 -> 223.38918 | L16: =ASN.HDB!H2750 -> 0.58985549 | M16: =ASN.HDB!H4008 -> 157.0936
A17: 13 | B17: =ASN.HDB!C2751 -> 0.76565886 | C17: =ASN.HDB!C4009 -> 44.657768 | D17: =ASN.HDB!D2751 -> 0.41107187 | E17: =ASN.HDB!D4009 -> 46.235886 | F17: =ASN.HDB!E2751 -> 0.93030322 | G17: =ASN.HDB!E4009 -> 320.67145 | H17: =ASN.HDB!F2751 -> 1.0442944 | I17: =ASN.HDB!F4009 -> 16.175785 | J17: =ASN.HDB!G2751 -> 1.3314903 | K17: =ASN.HDB!G4009 -> 216.62202 | L17: =ASN.HDB!H2751 -> 0.51910532 | M17: =ASN.HDB!H4009 -> 150.08746
A18: 14 | B18: =ASN.HDB!C2752 -> 0.7852459 | C18: =ASN.HDB!C4010 -> 38.517254 | D18: =ASN.HDB!D2752 -> 0.42754409 | E18: =ASN.HDB!D4010 -> 39.917244 | F18: =ASN.HDB!E2752 -> 0.94854236 | G18: =ASN.HDB!E4010 -> 313.30624 | H18: =ASN.HDB!F2752 -> 0.81139445 | I18: =ASN.HDB!F4010 -> 14.01488 | J18: =ASN.HDB!G2752 -> 1.1477923 | K18: =ASN.HDB!G4010 -> 211.33519 | L18: =ASN.HDB!H2752 -> 0.46046486 | M18: =ASN.HDB!H4010 -> 145.14355
... A39: 35 | B39: =ASN.HDB!C2773 -> 1.0390576 | C39: =ASN.HDB!C4031 -> 7.314198 | D39: =ASN.HDB!D2773 -> 0.59575152 | E39: =ASN.HDB!D4031 -> 7.6654067 | F39: =ASN.HDB!E2773 -> 0.99821907 | G39: =ASN.HDB!E4031 -> 278.12643 | H39: =ASN.HDB!F2773 -> 0.11423544 | I39: =ASN.HDB!F4031 -> 3.2455409 | J39: =ASN.HDB!G2773 -> 0.21927942 | K39: =ASN.HDB!G4031 -> 185.21048 | L39: =ASN.HDB!H2773 -> 0.17977925 | M39: =ASN.HDB!H4031 -> 149.7032

Sheet 40°
A1: ='0°'!A1 -> RAOs for Ile de Molene
A3: Direction = 40°
A4: Period | B4: Surge | D4: Sway | F4: Heave | H4: Roll | J4: Pitch | L4: Yaw
B5: Ampl. | C5: Phase | D5: Ampl. | E5: Phase | F5: Ampl. | G5: Phase | H5: Ampl. | I5: Phase | J5: Ampl. | K5: Phase | L5: Ampl. | M5: Phase
A6: (s) | B6: m/m | C6: deg | D6: m/m | E6: deg | F6: m/m | G6: deg | H6: deg/m | I6: deg | J6: deg/m | K6: deg | L6: deg/m | M6: deg
A7: 3 | B7: =ASN.HDB!C2775 -> 0.0034327665 | C7: =ASN.HDB!C4033 -> 314.85507 | D7: =ASN.HDB!D2775 -> 0.0010185331 | E7: =ASN.HDB!D4033 -> 224.03777 | F7: =ASN.HDB!E2775 -> 0.0021323594 | G7: =ASN.HDB!E4033 -> 279.52344 | H7: =ASN.HDB!F2775 -> 0.061158277 | I7: =ASN.HDB!F4033 -> 68.295517 | J7: =ASN.HDB!G2775 -> 0.016588336 | K7: =ASN.HDB!G4033 -> 263.56198 | L7: =ASN.HDB!H2775 -> 0.015615494 | M7: =ASN.HDB!H4033 -> 100.13186
A8: 4 | B8: =ASN.HDB!C2776 -> 0.007380221 | C8: =ASN.HDB!C4034 -> 3.8279626 | D8: =ASN.HDB!D2776 -> 0.0096757226 | E8: =ASN.HDB!D4034 -> 137.02982 | F8: =ASN.HDB!E2776 -> 0.02288112 | G8: =ASN.HDB!E4034 -> 345.95276 | H8: =ASN.HDB!F2776 -> 0.22768219 | I8: =ASN.HDB!F4034 -> 142.53284 | J8: =ASN.HDB!G2776 -> 0.16961156 | K8: =ASN.HDB!G4034 -> 352.74756 | L8: =ASN.HDB!H2776 -> 0.054733709 | M8: =ASN.HDB!H4034 -> 162.72215
A9: 5 | B9: =ASN.HDB!C2777 -> 0.0091402354 | C9: =ASN.HDB!C4035 -> 339.31357 | D9: =ASN.HDB!D2777 -> 0.018881975 | E9: =ASN.HDB!D4035 -> 130.37988 | F9: =ASN.HDB!E2777 -> 0.072878376 | G9: =ASN.HDB!E4035 -> 11.66109 | H9: =ASN.HDB!F2777 -> 0.52075219 | I9: =ASN.HDB!F4035 -> 180.81032 | J9: =ASN.HDB!G2777 -> 0.49222487 | K9: =ASN.HDB!G4035 -> 356.16754 | L9: =ASN.HDB!H2777 -> 0.083638974 | M9: =ASN.HDB!H4035 -> 213.69966
A10: 6 | B10: =ASN.HDB!C2778 -> 0.074939609 | C10: =ASN.HDB!C4036 -> 192.88873 | D10: =ASN.HDB!D2778 -> 0.0082771135 | E10: =ASN.HDB!D4036 -> 110.77662 | F10: =ASN.HDB!E2778 -> 0.18966043 | G10: =ASN.HDB!E4036 -> 305.97195 | H10: =ASN.HDB!F2778 -> 0.58329052 | I10: =ASN.HDB!F4036 -> 161.58536 | J10: =ASN.HDB!G2778 -> 1.2073742 | K10: =ASN.HDB!G4036 -> 4.1848907 | L10: =ASN.HDB!H2778 -> 0.39004284 | M10: =ASN.HDB!H4036 -> 294.37778
A11: 7 | B11: =ASN.HDB!C2779 -> 0.23828094 | C11: =ASN.HDB!C4037 -> 155.42722 | D11: =ASN.HDB!D2779 -> 0.1280136 | E11: =ASN.HDB!D4037 -> 140.51254 | F11: =ASN.HDB!E2779 -> 0.2298526 | G11: =ASN.HDB!E4037 -> 147.41887 | H11: =ASN.HDB!F2779 -> 0.90458143 | I11: =ASN.HDB!F4037 -> 188.08923 | J11: =ASN.HDB!G2779 -> 2.6248741 | K11: =ASN.HDB!G4037 -> 327.20041 | L11: =ASN.HDB!H2779 -> 0.74866438 | M11: =ASN.HDB!H4037 -> 239.37482
A12: 8 | B12: =ASN.HDB!C2780 -> 0.44811645 | C12: =ASN.HDB!C4038 -> 115.7264 | D12: =ASN.HDB!D2780 -> 0.24490705 | E12: =ASN.HDB!D4038 -> 108.47161 | F12: =ASN.HDB!E2780 -> 0.54194826 | G12: =ASN.HDB!E4038 -> 56.719582 | H12: =ASN.HDB!F2780 -> 1.926707 | I12: =ASN.HDB!F4038 -> 189.73137 | J12: =ASN.HDB!G2780 -> 3.0569162 | K12: =ASN.HDB!G4038 -> 284.01566 | L12: =ASN.HDB!H2780 -> 0.83430207 | M12: =ASN.HDB!H4038 -> 204.48672
A13: 9 | B13: =ASN.HDB!C2781 -> 0.5594939 | C13: =ASN.HDB!C4039 -> 86.325401 | D13: =ASN.HDB!D2781 -> 0.3375344 | E13: =ASN.HDB!D4039 -> 88.922195 | F13: =ASN.HDB!E2781 -> 0.74343723 | G13: =ASN.HDB!E4039 -> 15.07066 | H13: =ASN.HDB!F2781 -> 4.6455402 | I13: =ASN.HDB!F4039 -> 159.58784 | J13: =ASN.HDB!G2781 -> 2.5997262 | K13: =ASN.HDB!G4039 -> 254.44305 | L13: =ASN.HDB!H2781 -> 0.73222518 | M13: =ASN.HDB!H4039 -> 185.23317
A14: 10 | B14: =ASN.HDB!C2782 -> 0.61243397 | C14: =ASN.HDB!C4040 -> 67.855156 | D14: =ASN.HDB!D2782 -> 0.44382674 | E14: =ASN.HDB!D4040 -> 71.343407 | F14: =ASN.HDB!E2782 -> 0.84363776 | G14: =ASN.HDB!E4040 -> 350.61359 | H14: =ASN.HDB!F2782 -> 5.9340668 | I14: =ASN.HDB!F4040 -> 74.458389 | J14: =ASN.HDB!G2782 -> 2.083406 | K14: =ASN.HDB!G4040 -> 236.77861 | L14: =ASN.HDB!H2782 -> 0.82968426 | M14: =ASN.HDB!H4040 -> 180.23271
A15: 11 | B15: =ASN.HDB!C2783 -> 0.64612126 | C15: =ASN.HDB!C4041 -> 55.452198 | D15: =ASN.HDB!D2783 -> 0.48321855 | E15: =ASN.HDB!D4041 -> 56.927376 | F15: =ASN.HDB!E2783 -> 0.8975876 | G15: =ASN.HDB!E4041 -> 334.55188 | H15: =ASN.HDB!F2783 -> 3.0882845 | I15: =ASN.HDB!F4041 -> 27.565954 | J15: =ASN.HDB!G2783 -> 1.6953498 | K15: =ASN.HDB!G4041 -> 225.49741 | L15: =ASN.HDB!H2783 -> 0.78970021 | M15: =ASN.HDB!H4041 -> 161.76053
A16: 12 | B16: =ASN.HDB!C2784 -> 0.67077923 | C16: =ASN.HDB!C4042 -> 46.429909 | D16: =ASN.HDB!D2784 -> 0.51355118 | E16: =ASN.HDB!D4042 -> 47.909424 | F16: =ASN.HDB!E2784 -> 0.92937285 | G16: =ASN.HDB!E4042 -> 323.19452 | H16: =ASN.HDB!F2784 -> 1.8813132 | I16: =ASN.HDB!F4042 -> 18.223795 | J16: =ASN.HDB!G2784 -> 1.4102771 | K16: =ASN.HDB!G4042 -> 217.57961 | L16: =ASN.HDB!H2784 -> 0.68533653 | M16: =ASN.HDB!H4042 -> 152.30011
A17: 13 | B17: =ASN.HDB!C2785 -> 0.68947029 | C17: =ASN.HDB!C4043 -> 39.531464 | D17: =ASN.HDB!D2785 -> 0.53807044 | E17: =ASN.HDB!D4043 -> 40.90543 | F17: =ASN.HDB!E2785 -> 0.94940704 | G17: =ASN.HDB!E4043 -> 314.7576 | H17: =ASN.HDB!F2785 -> 1.3488197 | I17: =ASN.HDB!F4043 -> 14.723527 | J17: =ASN.HDB!G2785 -> 1.1943647 | K17: =ASN.HDB!G4043 -> 211.64836 | L17: =ASN.HDB!H2785 -> 0.60145098 | M17: =ASN.HDB!H4043 -> 146.31754
A18: 14 | B18: =ASN.HDB!C2786 -> 0.70381504 | C18: =ASN.HDB!C4044 -> 34.091602 | D18: =ASN.HDB!D2786 -> 0.55698526 | E18: =ASN.HDB!D4044 -> 35.312115 | F18: =ASN.HDB!E2786 -> 0.96270353 | G18: =ASN.HDB!E4044 -> 308.26685 | H18: =ASN.HDB!F2786 -> 1.0469626 | I18: =ASN.HDB!F4044 -> 12.624355 | J18: =ASN.HDB!G2786 -> 1.0258679 | K18: =ASN.HDB!G4044 -> 207.02168 | L18: =ASN.HDB!H2786 -> 0.53286201 | M18: =ASN.HDB!H4044 -> 142.27815
... A39: 35 | B39: =ASN.HDB!C2807 -> 0.9195509 | C39: =ASN.HDB!C4065 -> 6.4369769 | D39: =ASN.HDB!D2807 -> 0.76624465 | E39: =ASN.HDB!D4065 -> 6.785861 | F39: =ASN.HDB!E2807 -> 0.9987433 | G39: =ASN.HDB!E4065 -> 277.18808 | H39: =ASN.HDB!F2807 -> 0.14692807 | I39: =ASN.HDB!F4065 -> 2.8534594 | J39: =ASN.HDB!G2807 -> 0.1940559 | K39: =ASN.HDB!G4065 -> 184.2661 | L39: =ASN.HDB!H2807 -> 0.22169113 | M39: =ASN.HDB!H4065 -> 152.09088

Sheet 50°
A1: ='0°'!A1 -> RAOs for Ile de Molene
A3: Direction = 50°
A4: Period | B4: Surge | D4: Sway | F4: Heave | H4: Roll | J4: Pitch | L4: Yaw
B5: Ampl. | C5: Phase | D5: Ampl. | E5: Phase | F5: Ampl. | G5: Phase | H5: Ampl. | I5: Phase | J5: Ampl. | K5: Phase | L5: Ampl. | M5: Phase
A6: (s) | B6: m/m | C6: deg | D6: m/m | E6: deg | F6: m/m | G6: deg | H6: deg/m | I6: deg | J6: deg/m | K6: deg | L6: deg/m | M6: deg
A7: 3 | B7: =ASN.HDB!C2809 -> 0.0021234762 | C7: =ASN.HDB!C4067 -> 346.164 | D7: =ASN.HDB!D2809 -> 0.0042641875 | E7: =ASN.HDB!D4067 -> 233.01091 | F7: =ASN.HDB!E2809 -> 0.0023645191 | G7: =ASN.HDB!E4067 -> 229.55833 | H7: =ASN.HDB!F2809 -> 0.045956597 | I7: =ASN.HDB!F4067 -> 52.225197 | J7: =ASN.HDB!G2809 -> 0.0181135 | K7: =ASN.HDB!G4067 -> 231.13432 | L7: =ASN.HDB!H2809 -> 0.0055885911 | M7: =ASN.HDB!H4067 -> 207.33003
A8: 4 | B8: =ASN.HDB!C2810 -> 0.0064317822 | C8: =ASN.HDB!C4068 -> 9.7608242 | D8: =ASN.HDB!D2810 -> 0.016421666 | E8: =ASN.HDB!D4068 -> 19.347773 | F8: =ASN.HDB!E2810 -> 0.017309481 | G8: =ASN.HDB!E4068 -> 331.92908 | H8: =ASN.HDB!F2810 -> 0.17519282 | I8: =ASN.HDB!F4068 -> 120.00849 | J8: =ASN.HDB!G2810 -> 0.17393841 | K8: =ASN.HDB!G4068 -> 340.35696 | L8: =ASN.HDB!H2810 -> 0.031310178 | M8: =ASN.HDB!H4068 -> 354.30832
A9: 5 | B9: =ASN.HDB!C2811 -> 0.018693725 | C9: =ASN.HDB!C4069 -> 270.21881 | D9: =ASN.HDB!D2811 -> 0.031419206 | E9: =ASN.HDB!D4069 -> 83.988228 | F9: =ASN.HDB!E2811 -> 0.085545085 | G9: =ASN.HDB!E4069 -> 0.30945912 | H9: =ASN.HDB!F2811 -> 0.6082232 | I9: =ASN.HDB!F4069 -> 154.92213 | J9: =ASN.HDB!G2811 -> 0.42461392 | K9: =ASN.HDB!G4069 -> 4.0129128 | L9: =ASN.HDB!H2811 -> 0.04152894 | M9: =ASN.HDB!H4069 -> 302.46524
A10: 6 | B10: =ASN.HDB!C2812 -> 0.10275458 | C10: =ASN.HDB!C4070 -> 176.40765 | D10: =ASN.HDB!D2812 -> 0.05402891 | E10: =ASN.HDB!D4070 -> 145.75104 | F10: =ASN.HDB!E2812 -> 0.1257005 | G10: =ASN.HDB!E4070 -> 273.31778 | H10: =ASN.HDB!F2812 -> 0.62525123 | I10: =ASN.HDB!F4070 -> 173.18279 | J10: =ASN.HDB!G2812 -> 1.6691059 | K10: =ASN.HDB!G4070 -> 356.75397 | L10: =ASN.HDB!H2812 -> 0.60197246 | M10: =ASN.HDB!H4070 -> 257.30579
A11: 7 | B11: =ASN.HDB!C2813 -> 0.26985073 | C11: =ASN.HDB!C4071 -> 137.59793 | D11: =ASN.HDB!D2813 -> 0.21205074 | E11: =ASN.HDB!D4071 -> 115.65515 | F11: =ASN.HDB!E2813 -> 0.33864942 | G11: =ASN.HDB!E4071 -> 95.930901 | H11: =ASN.HDB!F2813 -> 1.2438573 | I11: =ASN.HDB!F4071 -> 185.94035 | J11: =ASN.HDB!G2813 -> 2.9302192 | K11: =ASN.HDB!G4071 -> 309.60703 | L11: =ASN.HDB!H2813 -> 0.89216787 | M11: =ASN.HDB!H4071 -> 213.91287
A12: 8 | B12: =ASN.HDB!C2814 -> 0.44136083 | C12: =ASN.HDB!C4072 -> 99.712234 | D12: =ASN.HDB!D2814 -> 0.34037441 | E12: =ASN.HDB!D4072 -> 90.04734 | F12: =ASN.HDB!E2814 -> 0.67919737 | G12: =ASN.HDB!E4072 -> 31.687016 | H12: =ASN.HDB!F2814 -> 2.4477468 | I12: =ASN.HDB!F4072 -> 182.28647 | J12: =ASN.HDB!G2814 -> 2.9610455 | K12: =ASN.HDB!G4072 -> 268.03412 | L12: =ASN.HDB!H2814 -> 0.91095304 | M12: =ASN.HDB!H4072 -> 185.47746
A13: 9 | B13: =ASN.HDB!C2815 -> 0.51449424 | C13: =ASN.HDB!C4073 -> 73.28791 | D13: =ASN.HDB!D2815 -> 0.43860069 | E13: =ASN.HDB!D4073 -> 74.302002 | F13: =ASN.HDB!E2815 -> 0.83809721 | G13: =ASN.HDB!E4073 -> 357.76816 | H13: =ASN.HDB!F2815 -> 5.3675823 | I13: =ASN.HDB!F4073 -> 150.88356 | J13: =ASN.HDB!G2815 -> 2.3589191 | K13: =ASN.HDB!G4073 -> 241.44994 | L13: =ASN.HDB!H2815 -> 0.75885206 | M13: =ASN.HDB!H4073 -> 170.786
A14: 10 | B14: =ASN.HDB!C2816 -> 0.54418766 | C14: =ASN.HDB!C4074 -> 57.227295 | D14: =ASN.HDB!D2816 -> 0.55183554 | E14: =ASN.HDB!D4074 -> 60.352608 | F14: =ASN.HDB!E2816 -> 0.90560478 | G14: =ASN.HDB!E4074 -> 337.43454 | H14: =ASN.HDB!F2816 -> 6.5888624 | I14: =ASN.HDB!F4074 -> 73.495941 | J14: =ASN.HDB!G2816 -> 1.8327736 | K14: =ASN.HDB!G4074 -> 226.22363 | L14: =ASN.HDB!H2816 -> 0.83050627 | M14: =ASN.HDB!H4074 -> 170.95932
A15: 11 | B15: =ASN.HDB!C2817 -> 0.56324011 | C15: =ASN.HDB!C4075 -> 46.64661 | D15: =ASN.HDB!D2817 -> 0.59770185 | E15: =ASN.HDB!D4075 -> 47.904396 | F15: =ASN.HDB!E2817 -> 0.93914551 | G15: =ASN.HDB!E4075 -> 324.03745 | H15: =ASN.HDB!F2817 -> 3.6762915 | I15: =ASN.HDB!F4075 -> 26.562965 | J15: =ASN.HDB!G2817 -> 1.4672511 | K15: =ASN.HDB!G4075 -> 216.76111 | L15: =ASN.HDB!H2817 -> 0.81223845 | M15: =ASN.HDB!H4075 -> 155.11282
A16: 12 | B16: =ASN.HDB!C2818 -> 0.57798755 | C16: =ASN.HDB!C4076 -> 39.018837 | D16: =ASN.HDB!D2818 -> 0.62843007 | E16: =ASN.HDB!D4076 -> 40.217712 | F16: =ASN.HDB!E2818 -> 0.95823193 | G16: =ASN.HDB!E4076 -> 314.55475 | H16: =ASN.HDB!F2818 -> 2.2517011 | I16: =ASN.HDB!F4076 -> 16.396015 | J16: =ASN.HDB!G2818 -> 1.2089725 | K16: =ASN.HDB!G4076 -> 210.21126 | L16: =ASN.HDB!H2818 -> 0.70425534 | M16: =ASN.HDB!H4076 -> 146.97263
A17: 13 | B17: =ASN.HDB!C2819 -> 0.58968455 | C17: =ASN.HDB!C4077 -> 33.209415 | D17: =ASN.HDB!D2819 -> 0.65358531 | E17: =ASN.HDB!D4077 -> 34.324303 | F17: =ASN.HDB!E2819 -> 0.97011036 | G17: =ASN.HDB!E4077 -> 307.50455 | H17: =ASN.HDB!F2819 -> 1.6138626 | I17: =ASN.HDB!F4077 -> 12.85181 | J17: =ASN.HDB!G2819 -> 1.0177788 | K17: =ASN.HDB!G4077 -> 205.33435 | L17: =ASN.HDB!H2819 -> 0.61697376 | M17: =ASN.HDB!H4077 -> 142.30424
A18: 14 | B18: =ASN.HDB!C2820 -> 0.59896296 | C18: =ASN.HDB!C4078 -> 28.63525 | D18: =ASN.HDB!D2820 -> 0.67319804 | E18: =ASN.HDB!D4078 -> 29.628731 | F18: =ASN.HDB!E2820 -> 0.97797734 | G18: =ASN.HDB!E4078 -> 302.07623 | H18: =ASN.HDB!F2820 -> 1.2519104 | I18: =ASN.HDB!F4078 -> 10.871044 | J18: =ASN.HDB!G2820 -> 0.87074554 | K18: =ASN.HDB!G4078 -> 201.53836 | L18: =ASN.HDB!H2820 -> 0.5466668 | M18: =ASN.HDB!H4078 -> 139.43695
... A39: 35 | B39: =ASN.HDB!C2841 -> 0.77200961 | C39: =ASN.HDB!C4099 -> 5.3481045 | D39: =ASN.HDB!D2841 -> 0.91363484 | E39: =ASN.HDB!D4099 -> 5.6934123 | F39: =ASN.HDB!E2841 -> 0.99930364 | G39: =ASN.HDB!E4099 -> 276.03137 | H39: =ASN.HDB!F2841 -> 0.17516559 | I39: =ASN.HDB!F4099 -> 2.4017215 | J39: =ASN.HDB!G2841 -> 0.16292912 | K39: =ASN.HDB!G4099 -> 183.02348 | L39: =ASN.HDB!H2841 -> 0.251257 | M39: =ASN.HDB!H4099 -> 155.53583

Sheet 60°
A1: ='0°'!A1 -> RAOs for Ile de Molene
A3: Direction = 60°
A4: Period | B4: Surge | D4: Sway | F4: Heave | H4: Roll | J4: Pitch | L4: Yaw
B5: Ampl. | C5: Phase | D5: Ampl. | E5: Phase | F5: Ampl. | G5: Phase | H5: Ampl. | I5: Phase | J5: Ampl. | K5: Phase | L5: Ampl. | M5: Phase
A6: (s) | B6: m/m | C6: deg | D6: m/m | E6: deg | F6: m/m | G6: deg | H6: deg/m | I6: deg | J6: deg/m | K6: deg | L6: deg/m | M6: deg
A7: 3 | B7: =ASN.HDB!C2843 -> 0.00078095659 | C7: =ASN.HDB!C4101 -> 47.950378 | D7: =ASN.HDB!D2843 -> 0.0045346152 | E7: =ASN.HDB!D4101 -> 280.46527 | F7: =ASN.HDB!E2843 -> 0.0038550012 | G7: =ASN.HDB!E4101 -> 218.79114 | H7: =ASN.HDB!F2843 -> 0.060673747 | I7: =ASN.HDB!F4101 -> 38.415966 | J7: =ASN.HDB!G2843 -> 0.024317658 | K7: =ASN.HDB!G4101 -> 202.41545 | L7: =ASN.HDB!H2843 -> 0.0082524624 | M7: =ASN.HDB!H4101 -> 328.80157
A8: 4 | B8: =ASN.HDB!C2844 -> 0.011113006 | C8: =ASN.HDB!C4102 -> 345.15561 | D8: =ASN.HDB!D2844 -> 0.0031108835 | E8: =ASN.HDB!D4102 -> 191.24634 | F8: =ASN.HDB!E2844 -> 0.013982184 | G8: =ASN.HDB!E4102 -> 355.00525 | H8: =ASN.HDB!F2844 -> 0.27894661 | I8: =ASN.HDB!F4102 -> 144.12572 | J8: =ASN.HDB!G2844 -> 0.14679775 | K8: =ASN.HDB!G4102 -> 312.75864 | L8: =ASN.HDB!H2844 -> 0.11037651 | M8: =ASN.HDB!H4102 -> 207.2386
A9: 5 | B9: =ASN.HDB!C2845 -> 0.024029562 | C9: =ASN.HDB!C4103 -> 199.30376 | D9: =ASN.HDB!D2845 -> 0.031046845 | E9: =ASN.HDB!D4103 -> 78.170471 | F9: =ASN.HDB!E2845 -> 0.064559639 | G9: =ASN.HDB!E4103 -> 338.83029 | H9: =ASN.HDB!F2845 -> 0.48147532 | I9: =ASN.HDB!F4103 -> 140.50854 | J9: =ASN.HDB!G2845 -> 0.6004467 | K9: =ASN.HDB!G4103 -> 11.442617 | L9: =ASN.HDB!H2845 -> 0.28706199 | M9: =ASN.HDB!H4103 -> 262.55115
A10: 6 | B10: =ASN.HDB!C2846 -> 0.11421847 | C10: =ASN.HDB!C4104 -> 153.79358 | D10: =ASN.HDB!D2846 -> 0.14646859 | E10: =ASN.HDB!D4104 -> 112.69556 | F10: =ASN.HDB!E2846 -> 0.053344686 | G10: =ASN.HDB!E4104 -> 128.27599 | H10: =ASN.HDB!F2846 -> 0.84939885 | I10: =ASN.HDB!F4104 -> 175.86925 | J10: =ASN.HDB!G2846 -> 2.0988493 | K10: =ASN.HDB!G4104 -> 336.93692 | L10: =ASN.HDB!H2846 -> 0.77785605 | M10: =ASN.HDB!H4104 -> 215.81154
A11: 7 | B11: =ASN.HDB!C2847 -> 0.27491832 | C11: =ASN.HDB!C4105 -> 116.85163 | D11: =ASN.HDB!D2847 -> 0.31763229 | E11: =ASN.HDB!D4105 -> 87.180328 | F11: =ASN.HDB!E2847 -> 0.53464222 | G11: =ASN.HDB!E4105 -> 52.244858 | H11: =ASN.HDB!F2847 -> 1.5385294 | I11: =ASN.HDB!F4105 -> 177.92175 | J11: =ASN.HDB!G2847 -> 3.0029197 | K11: =ASN.HDB!G4105 -> 287.34558 | L11: =ASN.HDB!H2847 -> 0.93080705 | M11: =ASN.HDB!H4105 -> 184.43466
A12: 8 | B12: =ASN.HDB!C2848 -> 0.40065309 | C12: =ASN.HDB!C4106 -> 81.24601 | D12: =ASN.HDB!D2848 -> 0.44295409 | E12: =ASN.HDB!D4106 -> 68.657196 | F12: =ASN.HDB!E2848 -> 0.83787781 | G12: =ASN.HDB!E4106 -> 5.230577 | H12: =ASN.HDB!F2848 -> 2.8318872 | I12: =ASN.HDB!F4106 -> 174.26332 | J12: =ASN.HDB!G2848 -> 2.6672719 | K12: =ASN.HDB!G4106 -> 248.65611 | L12: =ASN.HDB!H2848 -> 0.87224662 | M12: =ASN.HDB!H4106 -> 163.17116
A13: 9 | B13: =ASN.HDB!C2849 -> 0.43760267 | C13: =ASN.HDB!C4107 -> 58.15789 | D13: =ASN.HDB!D2849 -> 0.53601336 | E13: =ASN.HDB!D4107 -> 57.367622 | F13: =ASN.HDB!E2849 -> 0.93740147 | G13: =ASN.HDB!E4107 -> 338.47003 | H13: =ASN.HDB!F2849 -> 5.8656287 | I13: =ASN.HDB!F4107 -> 143.29265 | J13: =ASN.HDB!G2849 -> 1.9905297 | K13: =ASN.HDB!G4107 -> 225.66457 | L13: =ASN.HDB!H2849 -> 0.67511392 | M13: =ASN.HDB!H4107 -> 153.57454
A14: 10 | B14: =ASN.HDB!C2850 -> 0.44751793 | C14: =ASN.HDB!C4108 -> 44.87532 | D14: =ASN.HDB!D2850 -> 0.64931893 | E14: =ASN.HDB!D4108 -> 47.449852 | F14: =ASN.HDB!E2850 -> 0.96787244 | G14: =ASN.HDB!E4108 -> 322.46832 | H14: =ASN.HDB!F2850 -> 7.0921946 | I14: =ASN.HDB!F4108 -> 71.115311 | J14: =ASN.HDB!G2850 -> 1.4974484 | K14: =ASN.HDB!G4108 -> 213.35927 | L14: =ASN.HDB!H2850 -> 0.72605342 | M14: =ASN.HDB!H4108 -> 162.05957
A15: 11 | B15: =ASN.HDB!C2851 -> 0.45456028 | C15: =ASN.HDB!C4109 -> 36.419777 | D15: =ASN.HDB!D2851 -> 0.69906569 | E15: =ASN.HDB!D4109 -> 37.391384 | F15: =ASN.HDB!E2851 -> 0.97994399 | G15: =ASN.HDB!E4109 -> 312.00015 | H15: =ASN.HDB!F2851 -> 4.1381626 | I15: =ASN.HDB!F4109 -> 24.845623 | J15: =ASN.HDB!G2851 -> 1.1784929 | K15: =ASN.HDB!G4109 -> 206.09175 | L15: =ASN.HDB!H2851 -> 0.7396341 | M15: =ASN.HDB!H4109 -> 148.76256
A16: 12 | B16: =ASN.HDB!C2852 -> 0.4612163 | C16: =ASN.HDB!C4110 -> 30.42062 | D16: =ASN.HDB!D2852 -> 0.72812241 | E16: =ASN.HDB!D4110 -> 31.289362 | F16: =ASN.HDB!E2852 -> 0.98617345 | G16: =ASN.HDB!E4110 -> 304.62112 | H16: =ASN.HDB!F2852 -> 2.5513208 | I16: =ASN.HDB!F4110 -> 14.166612 | J16: =ASN.HDB!G2852 -> 0.96150368 | K16: =ASN.HDB!G4110 -> 201.19562 | L16: =ASN.HDB!H2852 -> 0.6431638 | M16: =ASN.HDB!H4110 -> 142.16602
A17: 13 | B17: =ASN.HDB!C2853 -> 0.46717003 | C17: =ASN.HDB!C4111 -> 25.881067 | D17: =ASN.HDB!D2853 -> 0.75215507 | E17: =ASN.HDB!D4111 -> 26.691095 | F17: =ASN.HDB!E2853 -> 0.98998165 | G17: =ASN.HDB!E4111 -> 299.1445 | H17: =ASN.HDB!F2853 -> 1.8296336 | I17: =ASN.HDB!F4111 -> 10.652127 | J17: =ASN.HDB!G2853 -> 0.80449748 | K17: =ASN.HDB!G4111 -> 197.59105 | L17: =ASN.HDB!H2853 -> 0.56422377 | M17: =ASN.HDB!H4111 -> 139.10356
A18: 14 | B18: =ASN.HDB!C2854 -> 0.47225153 | C18: =ASN.HDB!C4112 -> 22.31435 | D18: =ASN.HDB!D2854 -> 0.77115476 | E18: =ASN.HDB!D4112 -> 23.039164 | F18: =ASN.HDB!E2854 -> 0.99255246 | G18: =ASN.HDB!E4112 -> 294.92981 | H18: =ASN.HDB!F2854 -> 1.4190371 | I18: =ASN.HDB!F4112 -> 8.8280821 | J18: =ASN.HDB!G2854 -> 0.6855092 | K18: =ASN.HDB!G4112 -> 194.79541 | L18: =ASN.HDB!H2854 -> 0.5017246 | M18: =ASN.HDB!H4112 -> 137.69272
... A39: 35 | B39: =ASN.HDB!C2875 -> 0.60083419 | C39: =ASN.HDB!C4133 -> 4.069098 | D39: =ASN.HDB!D2875 -> 1.0333717 | E39: =ASN.HDB!D4133 -> 4.425652 | F39: =ASN.HDB!E2875 -> 0.99982756 | G39: =ASN.HDB!E4133 -> 274.6915 | H39: =ASN.HDB!F2875 -> 0.19808392 | I39: =ASN.HDB!F4133 -> 1.8914036 | J39: =ASN.HDB!G2875 -> 0.12683871 | K39: =ASN.HDB!G4133 -> 181.39847 | L39: =ASN.HDB!H2875 -> 0.26941919 | M39: =ASN.HDB!H4133 -> 160.16333

Sheet 70°
A1: ='0°'!A1 -> RAOs for Ile de Molene
A3: Direction = 70°
A4: Period | B4: Surge | D4: Sway | F4: Heave | H4: Roll | J4: Pitch | L4: Yaw
B5: Ampl. | C5: Phase | D5: Ampl. | E5: Phase | F5: Ampl. | G5: Phase | H5: Ampl. | I5: Phase | J5: Ampl. | K5: Phase | L5: Ampl. | M5: Phase
A6: (s) | B6: m/m | C6: deg | D6: m/m | E6: deg | F6: m/m | G6: deg | H6: deg/m | I6: deg | J6: deg/m | K6: deg | L6: deg/m | M6: deg
A7: 3 | B7: =ASN.HDB!C2877 -> 0.0017259838 | C7: =ASN.HDB!C4135 -> 189.37675 | D7: =ASN.HDB!D2877 -> 0.0078368019 | E7: =ASN.HDB!D4135 -> 294.85645 | F7: =ASN.HDB!E2877 -> 0.0050755469 | G7: =ASN.HDB!E4135 -> 180.46899 | H7: =ASN.HDB!F2877 -> 0.070082493 | I7: =ASN.HDB!F4135 -> 6.9741302 | J7: =ASN.HDB!G2877 -> 0.050110634 | K7: =ASN.HDB!G4135 -> 195.34715 | L7: =ASN.HDB!H2877 -> 0.020564646 | M7: =ASN.HDB!H4135 -> 14.641833
A8: 4 | B8: =ASN.HDB!C2878 -> 0.0050210566 | C8: =ASN.HDB!C4136 -> 201.08148 | D8: =ASN.HDB!D2878 -> 0.034846362 | E8: =ASN.HDB!D4136 -> 41.39156 | F8: =ASN.HDB!E2878 -> 0.021779034 | G8: =ASN.HDB!E4136 -> 331.43155 | H8: =ASN.HDB!F2878 -> 0.33969927 | I8: =ASN.HDB!F4136 -> 95.001923 | J8: =ASN.HDB!G2878 -> 0.10597769 | K8: =ASN.HDB!G4136 -> 332.25497 | L8: =ASN.HDB!H2878 -> 0.082406037 | M8: =ASN.HDB!H4136 -> 176.39542
A9: 5 | B9: =ASN.HDB!C2879 -> 0.015967375 | C9: =ASN.HDB!C4137 -> 121.70277 | D9: =ASN.HDB!D2879 -> 0.096776336 | E9: =ASN.HDB!D4137 -> 80.192619 | F9: =ASN.HDB!E2879 -> 0.049808595 | G9: =ASN.HDB!E4137 -> 44.958675 | H9: =ASN.HDB!F2879 -> 0.48873645 | I9: =ASN.HDB!F4137 -> 148.56223 | J9: =ASN.HDB!G2879 -> 0.85431659 | K9: =ASN.HDB!G4137 -> 346.23569 | L9: =ASN.HDB!H2879 -> 0.54871452 | M9: =ASN.HDB!H4137 -> 199.00784
A10: 6 | B10: =ASN.HDB!C2880 -> 0.10032389 | C10: =ASN.HDB!C4138 -> 134.18492 | D10: =ASN.HDB!D2880 -> 0.27099723 | E10: =ASN.HDB!D4138 -> 71.65966 | F10: =ASN.HDB!E2880 -> 0.27784327 | G10: =ASN.HDB!E4138 -> 51.818459 | H10: =ASN.HDB!F2880 -> 1.0074728 | I10: =ASN.HDB!F4138 -> 161.88448 | J10: =ASN.HDB!G2880 -> 2.2155879 | K10: =ASN.HDB!G4138 -> 309.2832 | L10: =ASN.HDB!H2880 -> 0.80233032 | M10: =ASN.HDB!H4138 -> 170.94455
A11: 7 | B11: =ASN.HDB!C2881 -> 0.24283092 | C11: =ASN.HDB!C4139 -> 95.356514 | D11: =ASN.HDB!D2881 -> 0.42895913 | E11: =ASN.HDB!D4139 -> 56.006649 | F11: =ASN.HDB!E2881 -> 0.78191167 | G11: =ASN.HDB!E4139 -> 13.402664 | H11: =ASN.HDB!F2881 -> 1.6424938 | I11: =ASN.HDB!F4139 -> 168.19492 | J11: =ASN.HDB!G2881 -> 2.7169142 | K11: =ASN.HDB!G4139 -> 260.77115 | L11: =ASN.HDB!H2881 -> 0.81243402 | M11: =ASN.HDB!H4139 -> 151.756
A12: 8 | B12: =ASN.HDB!C2882 -> 0.31950253 | C12: =ASN.HDB!C4140 -> 61.129486 | D12: =ASN.HDB!D2882 -> 0.53921908 | E12: =ASN.HDB!D4140 -> 45.009327 | F12: =ASN.HDB!E2882 -> 0.99825853 | G12: =ASN.HDB!E4140 -> 337.77054 | H12: =ASN.HDB!F2882 -> 2.9973249 | I12: =ASN.HDB!F4140 -> 167.19429 | J12: =ASN.HDB!G2882 -> 2.1445723 | K12: =ASN.HDB!G4140 -> 225.41792 | L12: =ASN.HDB!H2882 -> 0.7010982 | M12: =ASN.HDB!H4140 -> 137.93852
A13: 9 | B13: =ASN.HDB!C2883 -> 0.32667303 | C13: =ASN.HDB!C4141 -> 41.349377 | D13: =ASN.HDB!D2883 -> 0.61847091 | E13: =ASN.HDB!D4141 -> 38.604706 | F13: =ASN.HDB!E2883 -> 1.0291315 | G13: =ASN.HDB!E4141 -> 317.72717 | H13: =ASN.HDB!F2883 -> 6.1701465 | I13: =ASN.HDB!F4141 -> 137.56982 | J13: =ASN.HDB!G2883 -> 1.4935807 | K13: =ASN.HDB!G4141 -> 206.37741 | L13: =ASN.HDB!H2883 -> 0.47959083 | M13: =ASN.HDB!H4141 -> 133.31429
A14: 10 | B14: =ASN.HDB!C2884 -> 0.3226282 | C14: =ASN.HDB!C4142 -> 31.103621 | D14: =ASN.HDB!D2884 -> 0.72642416 | E14: =ASN.HDB!D4142 -> 33.055794 | F14: =ASN.HDB!E2884 -> 1.0227805 | G14: =ASN.HDB!E4142 -> 306.17462 | H14: =ASN.HDB!F2884 -> 7.3965855 | I14: =ASN.HDB!F4142 -> 68.281189 | J14: =ASN.HDB!G2884 -> 1.0830865 | K14: =ASN.HDB!G4142 -> 197.45906 | L14: =ASN.HDB!H2884 -> 0.52776021 | M14: =ASN.HDB!H4142 -> 157.13365
A15: 11 | B15: =ASN.HDB!C2885 -> 0.32159874 | C15: =ASN.HDB!C4143 -> 25.037016 | D15: =ASN.HDB!D2885 -> 0.7791416 | E15: =ASN.HDB!D4143 -> 25.705618 | F15: =ASN.HDB!E2885 -> 1.0149859 | G15: =ASN.HDB!E4143 -> 298.81421 | H15: =ASN.HDB!F2885 -> 4.462409 | I15: =ASN.HDB!F4143 -> 22.598965 | J15: =ASN.HDB!G2885 -> 0.83579683 | K15: =ASN.HDB!G4143 -> 192.81575 | L15: =ASN.HDB!H2885 -> 0.5836724 | M15: =ASN.HDB!H4143 -> 145.34615
A16: 12 | B16: =ASN.HDB!C2886 -> 0.32278547 | C16: =ASN.HDB!C4144 -> 20.874876 | D16: =ASN.HDB!D2886 -> 0.80585951 | E16: =ASN.HDB!D4144 -> 21.394253 | F16: =ASN.HDB!E2886 -> 1.0097796 | G16: =ASN.HDB!E4144 -> 293.70209 | H16: =ASN.HDB!F2886 -> 2.769664 | I16: =ASN.HDB!F4144 -> 11.645625 | J16: =ASN.HDB!G2886 -> 0.67436153 | K16: =ASN.HDB!G4144 -> 189.91711 | L16: =ASN.HDB!H2886 -> 0.5130356 | M16: =ASN.HDB!H4144 -> 140.29312
A17: 13 | B17: =ASN.HDB!C2887 -> 0.3247751 | C17: =ASN.HDB!C4145 -> 17.76239 | D17: =ASN.HDB!D2887 -> 0.82800078 | E17: =ASN.HDB!D4145 -> 18.237015 | F17: =ASN.HDB!E2887 -> 1.0065961 | G17: =ASN.HDB!E4145 -> 289.93588 | H17: =ASN.HDB!F2887 -> 1.9885546 | I17: =ASN.HDB!F4145 -> 8.2133665 | J17: =ASN.HDB!G2887 -> 0.56045347 | K17: =ASN.HDB!G4145 -> 187.8497 | L17: =ASN.HDB!H2887 -> 0.45427811 | M17: =ASN.HDB!H4145 -> 139.10556
A18: 14 | B18: =ASN.HDB!C2888 -> 0.3268896 | C18: =ASN.HDB!C4146 -> 15.322418 | D18: =ASN.HDB!D2888 -> 0.84576315 | E18: =ASN.HDB!D4146 -> 15.742841 | F18: =ASN.HDB!E2888 -> 1.0046526 | G18: =ASN.HDB!E4146 -> 287.0477 | H18: =ASN.HDB!F2888 -> 1.5425403 | I18: =ASN.HDB!F4146 -> 6.5703835 | J18: =ASN.HDB!G2888 -> 0.47550008 | K18: =ASN.HDB!G4146 -> 186.25929 | L18: =ASN.HDB!H2888 -> 0.40907681 | M18: =ASN.HDB!H4146 -> 139.42647
... A39: 35 | B39: =ASN.HDB!C2909 -> 0.4112027 | C39: =ASN.HDB!C4167 -> 2.6037223 | D39: =ASN.HDB!D2909 -> 1.1217095 | E39: =ASN.HDB!D4167 -> 3.0224264 | F39: =ASN.HDB!E2909 -> 1.0002564 | G39: =ASN.HDB!E4167 -> 273.2092 | H39: =ASN.HDB!F2909 -> 0.21498986 | I39: =ASN.HDB!F4167 -> 1.324311 | J39: =ASN.HDB!G2909 -> 0.086893626 | K39: =ASN.HDB!G4167 -> 179.08052 | L39: =ASN.HDB!H2909 -> 0.27869654 | M39: =ASN.HDB!H4167 -> 166.02908

Sheet 80°
A1: ='0°'!A1 -> RAOs for Ile de Molene
A3: Direction = 80°
A4: Period | B4: Surge | D4: Sway | F4: Heave | H4: Roll | J4: Pitch | L4: Yaw
B5: Ampl. | C5: Phase | D5: Ampl. | E5: Phase | F5: Ampl. | G5: Phase | H5: Ampl. | I5: Phase | J5: Ampl. | K5: Phase | L5: Ampl. | M5: Phase
A6: (s) | B6: m/m | C6: deg | D6: m/m | E6: deg | F6: m/m | G6: deg | H6: deg/m | I6: deg | J6: deg/m | K6: deg | L6: deg/m | M6: deg
A7: 3 | B7: =ASN.HDB!C2911 -> 0.00122826 | C7: =ASN.HDB!C4169 -> 157.19086 | D7: =ASN.HDB!D2911 -> 0.018036149 | E7: =ASN.HDB!D4169 -> 304.49017 | F7: =ASN.HDB!E2911 -> 0.0040495736 | G7: =ASN.HDB!E4169 -> 261.51318 | H7: =ASN.HDB!F2911 -> 0.13163957 | I7: =ASN.HDB!F4169 -> 334.38348 | J7: =ASN.HDB!G2911 -> 0.031571891 | K7: =ASN.HDB!G4169 -> 154.93797 | L7: =ASN.HDB!H2911 -> 0.090964846 | M7: =ASN.HDB!H4169 -> 39.864536
A8: 4 | B8: =ASN.HDB!C2912 -> 0.011337608 | C8: =ASN.HDB!C4170 -> 354.0928 | D8: =ASN.HDB!D2912 -> 0.074102141 | E8: =ASN.HDB!D4170 -> 0.4740459 | F8: =ASN.HDB!E2912 -> 0.025882987 | G8: =ASN.HDB!E4170 -> 356.22137 | H8: =ASN.HDB!F2912 -> 0.19272898 | I8: =ASN.HDB!F4170 -> 79.855728 | J8: =ASN.HDB!G2912 -> 0.24362299 | K8: =ASN.HDB!G4170 -> 295.99814 | L8: =ASN.HDB!H2912 -> 0.3024745 | M8: =ASN.HDB!H4170 -> 137.79733
A9: 5 | B9: =ASN.HDB!C2913 -> 0.013701029 | C9: =ASN.HDB!C4171 -> 255.62299 | D9: =ASN.HDB!D2913 -> 0.2247213 | E9: =ASN.HDB!D4171 -> 27.940758 | F9: =ASN.HDB!E2913 -> 0.18417384 | G9: =ASN.HDB!E4171 -> 22.689041 | H9: =ASN.HDB!F2913 -> 0.52728182 | I9: =ASN.HDB!F4171 -> 124.42267 | J9: =ASN.HDB!G2913 -> 0.79991651 | K9: =ASN.HDB!G4171 -> 306.98129 | L9: =ASN.HDB!H2913 -> 0.56784374 | M9: =ASN.HDB!H4171 -> 131.01649
A10: 6 | B10: =ASN.HDB!C2914 -> 0.081806071 | C10: =ASN.HDB!C4172 -> 132.93149 | D10: =ASN.HDB!D2914 -> 0.39162889 | E10: =ASN.HDB!D4172 -> 27.232252 | F10: =ASN.HDB!E2914 -> 0.54693049 | G10: =ASN.HDB!E4172 -> 8.1817293 | H10: =ASN.HDB!F2914 -> 0.84382057 | I10: =ASN.HDB!F4172 -> 146.31783 | J10: =ASN.HDB!G2914 -> 1.8365214 | K10: =ASN.HDB!G4172 -> 277.53772 | L10: =ASN.HDB!H2914 -> 0.58467239 | M10: =ASN.HDB!H4172 -> 123.75507
A11: 7 | B11: =ASN.HDB!C2915 -> 0.17755748 | C11: =ASN.HDB!C4173 -> 77.665016 | D11: =ASN.HDB!D2915 -> 0.52049184 | E11: =ASN.HDB!D4173 -> 23.154243 | F11: =ASN.HDB!E2915 -> 1.0279665 | G11: =ASN.HDB!E4173 -> 336.45737 | H11: =ASN.HDB!F2915 -> 1.5238671 | I11: =ASN.HDB!F4173 -> 162.33023 | J11: =ASN.HDB!G2915 -> 2.0451555 | K11: =ASN.HDB!G4173 -> 229.30075 | L11: =ASN.HDB!H2915 -> 0.52231264 | M11: =ASN.HDB!H4173 -> 116.41573
A12: 8 | B12: =ASN.HDB!C2916 -> 0.20211379 | C12: =ASN.HDB!C4174 -> 40.814335 | D12: =ASN.HDB!D2916 -> 0.61219287 | E12: =ASN.HDB!D4174 -> 19.8958 | F12: =ASN.HDB!E2916 -> 1.1360221 | G12: =ASN.HDB!E4174 -> 309.68094 | H12: =ASN.HDB!F2916 -> 2.9692879 | I12: =ASN.HDB!F4174 -> 163.02667 | J12: =ASN.HDB!G2916 -> 1.4311181 | K12: =ASN.HDB!G4174 -> 195.54936 | L12: =ASN.HDB!H2916 -> 0.41048586 | M12: =ASN.HDB!H4174 -> 109.18733
A13: 9 | B13: =ASN.HDB!C2917 -> 0.18704642 | C13: =ASN.HDB!C4175 -> 23.163877 | D13: =ASN.HDB!D2917 -> 0.67486757 | E13: =ASN.HDB!D4175 -> 18.563595 | F13: =ASN.HDB!E2917 -> 1.1006794 | G13: =ASN.HDB!E4175 -> 296.05133 | H13: =ASN.HDB!F2917 -> 6.2682233 | I13: =ASN.HDB!F4175 -> 133.45555 | J13: =ASN.HDB!G2917 -> 0.90543234 | K13: =ASN.HDB!G4175 -> 179.67752 | L13: =ASN.HDB!H2917 -> 0.20049325 | M13: =ASN.HDB!H4175 -> 105.88087
A14: 10 | B14: =ASN.HDB!C2918 -> 0.17492718 | C14: =ASN.HDB!C4176 -> 15.998846 | D14: =ASN.HDB!D2918 -> 0.77408159 | E14: =ASN.HDB!D4176 -> 17.638849 | F14: =ASN.HDB!E2918 -> 1.0630894 | G14: =ASN.HDB!E4176 -> 289.00748 | H14: =ASN.HDB!F2918 -> 7.5665326 | I14: =ASN.HDB!F4176 -> 65.260727 | J14: =ASN.HDB!G2918 -> 0.61634791 | K14: =ASN.HDB!G4176 -> 174.36215 | L14: =ASN.HDB!H2918 -> 0.30439121 | M14: =ASN.HDB!H4176 -> 171.77025
A15: 11 | B15: =ASN.HDB!C2919 -> 0.16962111 | C15: =ASN.HDB!C4177 -> 12.62751 | D15: =ASN.HDB!D2919 -> 0.83021915 | E15: =ASN.HDB!D4177 -> 13.207305 | F15: =ASN.HDB!E2919 -> 1.0397519 | G15: =ASN.HDB!E4177 -> 284.86411 | H15: =ASN.HDB!F2919 -> 4.6500993 | I15: =ASN.HDB!F4177 -> 19.969702 | J15: =ASN.HDB!G2919 -> 0.45809698 | K15: =ASN.HDB!G4177 -> 172.95868 | L15: =ASN.HDB!H2919 -> 0.38976905 | M15: =ASN.HDB!H4177 -> 152.89067
A16: 12 | B16: =ASN.HDB!C2920 -> 0.16782868 | C16: =ASN.HDB!C4178 -> 10.567421 | D16: =ASN.HDB!D2920 -> 0.85539854 | E16: =ASN.HDB!D4178 -> 10.834179 | F16: =ASN.HDB!E2920 -> 1.0260676 | G16: =ASN.HDB!E4178 -> 282.12219 | H16: =ASN.HDB!F2920 -> 2.9012833 | I16: =ASN.HDB!F4178 -> 8.9115877 | J16: =ASN.HDB!G2920 -> 0.36163166 | K16: =ASN.HDB!G4178 -> 172.69373 | L16: =ASN.HDB!H2920 -> 0.35045698 | M16: =ASN.HDB!H4178 -> 148.38989
A17: 13 | B17: =ASN.HDB!C2921 -> 0.16753325 | C17: =ASN.HDB!C4179 -> 9.0682411 | D17: =ASN.HDB!D2921 -> 0.87594223 | E17: =ASN.HDB!D4179 -> 9.2198067 | F17: =ASN.HDB!E2921 -> 1.017876 | G17: =ASN.HDB!E4179 -> 280.15494 | H17: =ASN.HDB!F2921 -> 2.0855739 | I17: =ASN.HDB!F4179 -> 5.60602 | J17: =ASN.HDB!G2921 -> 0.29662535 | K17: =ASN.HDB!G4179 -> 172.7027 | L17: =ASN.HDB!H2921 -> 0.31992483 | M17: =ASN.HDB!H4179 -> 148.85533
A18: 14 | B18: =ASN.HDB!C2922 -> 0.16783947 | C18: =ASN.HDB!C4180 -> 7.8791118 | D18: =ASN.HDB!D2922 -> 0.8925885 | E18: =ASN.HDB!D4180 -> 7.9625401 | F18: =ASN.HDB!E2922 -> 1.0127791 | G18: =ASN.HDB!E4180 -> 278.66736 | H18: =ASN.HDB!F2922 -> 1.6182946 | I18: =ASN.HDB!F4180 -> 4.1612849 | J18: =ASN.HDB!G2922 -> 0.24958158 | K18: =ASN.HDB!G4180 -> 172.7495 | L18: =ASN.HDB!H2922 -> 0.29871979 | M18: =ASN.HDB!H4180 -> 150.62628
... A39: 35 | B39: =ASN.HDB!C2943 -> 0.20890756 | C39: =ASN.HDB!C4201 -> 0.82901442 | D39: =ASN.HDB!D2943 -> 1.1758584 | E39: =ASN.HDB!D4201 -> 1.5246426 | F39: =ASN.HDB!E2943 -> 1.0005342 | G39: =ASN.HDB!E4201 -> 271.62946 | H39: =ASN.HDB!F2943 -> 0.22535434 | I39: =ASN.HDB!F4201 -> 0.73266691 | J39: =ASN.HDB!G2943 -> 0.044393096 | K39: =ASN.HDB!G4201 -> 174.4054 | L39: =ASN.HDB!H2943 -> 0.28248286 | M39: =ASN.HDB!H4201 -> 172.96815

Sheet 90°
A1: ='0°'!A1 -> RAOs for Ile de Molene
A3: Direction = 90°
A4: Period | B4: Surge | D4: Sway | F4: Heave | H4: Roll | J4: Pitch | L4: Yaw
B5: Ampl. | C5: Phase | D5: Ampl. | E5: Phase | F5: Ampl. | G5: Phase | H5: Ampl. | I5: Phase | J5: Ampl. | K5: Phase | L5: Ampl. | M5: Phase
A6: (s) | B6: m/m | C6: deg | D6: m/m | E6: deg | F6: m/m | G6: deg | H6: deg/m | I6: deg | J6: deg/m | K6: deg | L6: deg/m | M6: deg
A7: 3 | B7: =ASN.HDB!C2945 -> 0.0033575522 | C7: =ASN.HDB!C4203 -> 110.23319 | D7: =ASN.HDB!D2945 -> 0.0537332 | E7: =ASN.HDB!D4203 -> 166.38777 | F7: =ASN.HDB!E2945 -> 0.019765811 | G7: =ASN.HDB!E4203 -> 172.10309 | H7: =ASN.HDB!F2945 -> 0.03472089 | I7: =ASN.HDB!F4203 -> 161.55186 | J7: =ASN.HDB!G2945 -> 0.048446763 | K7: =ASN.HDB!G4203 -> 153.29425 | L7: =ASN.HDB!H2945 -> 0.10188861 | M7: =ASN.HDB!H4203 -> 328.83658
A8: 4 | B8: =ASN.HDB!C2946 -> 0.019589238 | C8: =ASN.HDB!C4204 -> 167.60027 | D8: =ASN.HDB!D2946 -> 0.16474603 | E8: =ASN.HDB!D4204 -> 285.10809 | F8: =ASN.HDB!E2946 -> 0.078905717 | G8: =ASN.HDB!E4204 -> 295.85199 | H8: =ASN.HDB!F2946 -> 0.07836169 | I8: =ASN.HDB!F4204 -> 350.47787 | J8: =ASN.HDB!G2946 -> 0.1255431 | K8: =ASN.HDB!G4204 -> 230.83022 | L8: =ASN.HDB!H2946 -> 0.20648304 | M8: =ASN.HDB!H4204 -> 38.401707
A9: 5 | B9: =ASN.HDB!C2947 -> 0.04948055 | C9: =ASN.HDB!C4205 -> 172.48341 | D9: =ASN.HDB!D2947 -> 0.31887504 | E9: =ASN.HDB!D4205 -> 324.81686 | F9: =ASN.HDB!E2947 -> 0.29320464 | G9: =ASN.HDB!E4205 -> 329.48367 | H9: =ASN.HDB!F2947 -> 0.15684472 | I9: =ASN.HDB!F4205 -> 104.0099 | J9: =ASN.HDB!G2947 -> 0.3785463 | K9: =ASN.HDB!G4205 -> 279.13107 | L9: =ASN.HDB!H2947 -> 0.1985645 | M9: =ASN.HDB!H4205 -> 56.553612
A10: 6 | B10: =ASN.HDB!C2948 -> 0.10305912 | C10: =ASN.HDB!C4206 -> 134.91296 | D10: =ASN.HDB!D2948 -> 0.45834064 | E10: =ASN.HDB!D4206 -> 341.53894 | F10: =ASN.HDB!E2948 -> 0.75819278 | G10: =ASN.HDB!E4206 -> 325.4704 | H10: =ASN.HDB!F2948 -> 0.53841597 | I10: =ASN.HDB!F4206 -> 157.05667 | J10: =ASN.HDB!G2948 -> 1.0083852 | K10: =ASN.HDB!G4206 -> 246.883 | L10: =ASN.HDB!H2948 -> 0.14437258 | M10: =ASN.HDB!H4206 -> 72.745728
A11: 7 | B11: =ASN.HDB!C2949 -> 0.1082891 | C11: =ASN.HDB!C4207 -> 76.926834 | D11: =ASN.HDB!D2949 -> 0.56571198 | E11: =ASN.HDB!D4207 -> 349.71658 | F11: =ASN.HDB!E2949 -> 1.2146671 | G11: =ASN.HDB!E4207 -> 300.40784 | H11: =ASN.HDB!F2949 -> 1.3650548 | I11: =ASN.HDB!F4207 -> 164.8044 | J11: =ASN.HDB!G2949 -> 1.1235979 | K11: =ASN.HDB!G4207 -> 186.70523 | L11: =ASN.HDB!H2949 -> 0.1070529 | M11: =ASN.HDB!H4207 -> 70.393143
